Workbook

Sheet Saisie
B2: I1 | C2: I2 | D2: I3 | E2: I4 | F2: I5 | G2: I6 | H2: Q4 | I2: I7 | J2: I8 | K2: I9 | L2: I10 | M2: Q1 | Q2: Q6 | R2: Q7 | T2: Q8 | V2: Q9 | AG2: Q10 | AJ2: Q11 | AN2: Q12 | AS2: Q13 | AT2: Q14 | AU2: Q15 | AX2: Q16 | AZ2: Q17
B3: GUIDE DES OPERATIONS EN PSC (Décret n°2021-909 du 22 décembre 2021 fixant les modalités d'exécution des crédits budgétaires dans le cadre des procédures prévues par le Code des marchés publics) | H3: Article 6 | M3: Article 20.1 CMP | Q3: Article 6 | R3: Article 19.4 CMP | T3: Article 6 | V3: Article 6 | AG3: Article 6 | AJ3: Article 6 | AN3: Article 6 | AU3: Article 6 | AX3: Article 6 | AZ3: Arrêté interministériel N° 484 MEF/DGBF/DMP du 09 novembre 2011
B4: Montant supérieur ou égal à 10 000 000 FCFA et inférieur à 30 000 000 FCFA
A5: N° | B5: Contrôleur | C5: Date de contrôle | D5: Ministère | E5: Autorité Contractante | F5: Personne Ressource | G5: Imputation Budgétaire | H5: Montant de la dotation/ou du crédit : | I5: Numéro de l'opération | J5: Objet de l'opération | K5: Nature de l'opération | M5: Préparation du PSPM | Q5: Montant de l'estimation | R5: Opération réservée aux PME | T5: Formulaire de demande de cotation | V5: Liste des entreprises consultées & montant des offres | AG5: Formulaire de sélection | AJ5: Date et signature du formulaire de selection | AN5: Attributaire (s) | AS5: Ecart entre montant estimatif et montant attribué | AT5: Situation d'exécution de la ligne budgetaire après passation | AU5: Notification de l'attribution au (x) soumissionnaire (s) retenu (s) | AX5: Information des soumissionnaires non retenus | AZ5: Existence et exhaustivité de l’archivage des documents | BC5: Temps total pour la conduite de l’opération
B6: Nom de l'Agent DGMP | F6: Interlocuteur chez l'AC | H6: Montant | I6: N° formulaire de demande de cotation | K6: Travaux/ Fournitures/ Prestations | L6: Observations | M6: Existence du PSPM | N6: Observations | O6: Respect du PSPM | P6: Observations | Q6: Montant | R6: Constat | S6: Observations | T6: Conforme au modèle élaboré par la DGMP | U6: Observations | V6: Nombre de soumissionnaires | W6: Référence de l'accord pour consulter moins de trois (3) entreprises | X6: Entreprise 1 | AA6: Entreprise 2 | AD6: Entreprise 3 | AG6: Existence | AH6: Conforme au modèle DGMP | AI6: Observations | AJ6: Signature | AK6: Date | AL6: Qualité du signataire | AM6: Observations | AN6: Lot | AO6: Raison sociale | AP6: NCC attributaire | AQ6: Montant | AR6: Observations | AS6: Montant | AT6: Montant disponible | AU6: Constat | AV6: Date | AW6: Observations | AX6: Constat | AY6: Observations | AZ6: Existence | BA6: Exhaustivité | BB6: Observations | BC6: Nombre de jour de l'opération | BD6: Observations
K7: PRESTATIONS | BC7: =IF(OR(#REF!="",#REF!="")=TRUE,"",NETWORKDAYS.INTL(#REF!,#REF!)) -> #REF!
BC8: =IF(OR(#REF!="",#REF!="")=TRUE,"",NETWORKDAYS.INTL(#REF!,#REF!)) -> #REF!
BC9: =IF(OR(#REF!="",#REF!="")=TRUE,"",NETWORKDAYS.INTL(#REF!,#REF!)) -> #REF!
BC10: =IF(OR(#REF!="",#REF!="")=TRUE,"",NETWORKDAYS.INTL(#REF!,#REF!)) -> #REF!
BC11: =IF(OR(#REF!="",#REF!="")=TRUE,"",NETWORKDAYS.INTL(#REF!,#REF!)) -> #REF!
BC12: =IF(OR(#REF!="",#REF!="")=TRUE,"",NETWORKDAYS.INTL(#REF!,#REF!)) -> #REF!
BC13: =IF(OR(#REF!="",#REF!="")=TRUE,"",NETWORKDAYS.INTL(#REF!,#REF!)) -> #REF!
BC14: =IF(OR(#REF!="",#REF!="")=TRUE,"",NETWORKDAYS.INTL(#REF!,#REF!)) -> #REF!
BC15: =IF(OR(#REF!="",#REF!="")=TRUE,"",NETWORKDAYS.INTL(#REF!,#REF!)) -> #REF!
BC16: =IF(OR(#REF!="",#REF!="")=TRUE,"",NETWORKDAYS.INTL(#REF!,#REF!)) -> #REF!
BC17: =IF(OR(#REF!="",#REF!="")=TRUE,"",NETWORKDAYS.INTL(#REF!,#REF!)) -> #REF!
BC18: #REF!
BC19: #REF!
BC20: #REF!
BC21: #REF!
BC22: #REF!
BC23: #REF!
BC24: #REF!
BC25: #REF!
BC26: #REF!
BC27: #REF!
BC28: #REF!
BC29: #REF!
... BC117: #REF!
BC118: #REF! | BD118: Dossier incomplet dans l'ensemble
BC119: #REF! | BD119: Dossier incomplet dans l'ensemble
BC120: #REF! | BD120: Dossier incomplet dans l'ensemble
BC121: #REF! | BD121: Dossier incomplet dans l'ensemble
BC122: #REF! | BD122: Dossier incomplet dans l'ensemble
BC123: #REF! | BD123: Dossier incomplet dans l'ensemble
BC124: #REF!
BC125: #REF!
BC126: #REF!
BC127: #REF!
BC128: #REF!
...

Sheet Formule
B2: I1 | C2: I2 | D2: I3 | E2: I4 | F2: I5 | G2: I6 | H2: I7 | I2: I8 | J2: I9 | K2: I10 | M2: Q1 | Q2: Q2 | V2: Q3 | Y2: Q4 | Z2: Q5 | AA2: Q6 | AB2: Q7 | AD2: Q8 | AF2: Q9 | AQ2: Q10 | AT2: Q11 | AX2: Q12 | BC2: Q13 | BD2: Q14 | BE2: Q15 | BH2: Q16 | BJ2: Q17
B3: GUIDE DES OPERATIONS EN PSC (Décret n°2021-909 du 22 décembre 2021 fixant les modalités d'exécution des crédits budgétaires dans le cadre des procédures prévues par le Code des marchés publics) | M3: Article 20.1 CMP | Q3: Article 20.2 CMP | V3: Article 20.3 CMP | Y3: Article 6 | AA3: Article 6 | AB3: Article 19.4 CMP | AD3: Article 6 | AF3: Article 6 | AQ3: Article 6 | AT3: Article 6 | AX3: Article 6 | BE3: Article 6 | BH3: Article 6 | BJ3: Arrêté interministériel N° 484 MEF/DGBF/DMP du 09 novembre 2011
B4: Montant supérieur ou égal à 10 000 000 FCFA et inférieur à 30 000 000 FCFA
A5: N° | B5: Contrôleur | C5: Date de contrôle | D5: Ministère | E5: Autorité Contractante | F5: Personne Ressource | G5: Imputation Budgétaire | H5: Numéro de l'opération | I5: Objet de l'opération | J5: Nature de l'opération | M5: Préparation du PSPM | Q5: Publication du PSPM | V5: Inscription de l’opération au PSPM et respect du PSPM | Y5: Montant de la dotation/ou du crédit : | Z5: Situation d'exécution de la ligne budgetaire avant passation | AA5: Montant de l'estimation | AB5: Opération réservée aux PME | AD5: Formulaire de demande de cotation | AF5: Liste des entreprises consultées & montant des offres | AQ5: Formulaire de sélection | AT5: Date et signature du formulaire de selection | AX5: Attributaire (s) | BC5: Ecart entre montant estimatif et montant attribué | BD5: Situation d'exécution de la ligne budgetaire après passation | BE5: Notification de l'attribution au (x) soumissionnaire (s) retenu (s) | BH5: Information des soumissionnaires non retenus | BJ5: Existence et exhaustivité de l’archivage des documents | BM5: Temps total pour la conduite de l’opération
B6: Nom de l'Agent DGMP | F6: Interlocuteur chez l'AC | H6: N° formulaire de demande de cotation | J6: Travaux/ Fournitures/ Prestations | K6: Observations | L6: NB | M6: Existence du PSPM | N6: Date de notification du budget à l'AC | O6: Date de soumission du PSPM à la DGMP pour validation | P6: Observations | Q6: Constat | R6: Date | S6: Support | T6: Numéro du BOMP | U6: Observations | V6: Opération inscrite au PSPM | W6: Respect du PSPM | X6: Observations | Y6: Montant | Z6: Montant disponible | AA6: Montant | AB6: Constat | AC6: Observations | AD6: Conforme au modèle élaboré par la DGMP | AE6: Observations | AF6: Nombre de soumissionnaires | AG6: Référence de l'accord pour consulter moins de cinq entreprises | AH6: Entreprise 1 | AK6: Entreprise 2 | AN6: Entreprise 3 | AQ6: Existence | AR6: Conforme au modèle DGMP | AS6: Observations | AT6: Signature | AU6: Date | AV6: Qualité du signataire | AW6: Observations | AX6: Lot | AY6: Raison sociale | AZ6: NCC attributaire | BA6: Montant | BB6: Observations | BC6: Montant | BD6: Montant disponible | BE6: Constat | BF6: Date | BG6: Observations | BH6: Constat | BI6: Observations | BJ6: Existence | BK6: Exhaustivité | BL6: Observations | BM6: Nombre de jour de l'opération | BN6: Observations
A7: 1 | B7: =Saisie!B7 -> 0 | C7: =Saisie!C7 -> 0 | D7: =Saisie!D7 -> 0 | E7: =Saisie!E7 -> 0 | F7: =Saisie!F7 -> 0 | G7: =Saisie!G7 -> 0 | H7: =Saisie!I7 -> 0 | I7: =Saisie!J7 -> 0 | J7: =Saisie!K7 -> PRESTATIONS | K7: =Saisie!L7 -> 0 | L7: =Saisie!#REF! -> #REF! | M7: {=_xlfn.IFS(Saisie!M7="OUI",1,Saisie!M7="NON",0)} -> #N/A | N7: =Saisie!#REF! -> #REF! | O7: =Saisie!#REF! -> #REF! | P7: =Saisie!N7 -> 0 | Q7: {=_xlfn.IFS(Saisie!#REF!="OUI",1,Saisie!#REF!="NON",0)} -> #REF! | R7: =Saisie!#REF! -> #REF! | S7: =Saisie!#REF! -> #REF! | T7: =Saisie!#REF! -> #REF! | U7: =Saisie!#REF! -> #REF! | V7: {=_xlfn.IFS(Saisie!#REF!="OUI",1,Saisie!#REF!="NON",0)} -> #REF! | W7: {=_xlfn.IFS(Saisie!O7="OUI",1,Saisie!O7="NON",0)} -> #N/A | X7: =Saisie!P7 -> 0 | Y7: =Saisie!H7 -> 0 | Z7: =Saisie!#REF! -> #REF! | AA7: =Saisie!Q7 -> 0 | AB7: {=_xlfn.IFS(Saisie!R7="OUI",1,Saisie!R7="NON",0)} -> #N/A | AC7: =Saisie!S7 -> 0 | AD7: {=_xlfn.IFS(Saisie!T7="OUI",1,Saisie!T7="NON",0)} -> #N/A | AE7: =Saisie!U7 -> 0 | AF7: 3 | AG7: =Saisie!W7 -> 0 | AH7: =Saisie!X7 -> 0 | AI7: =Saisie!Y7 -> 0 | AJ7: =Saisie!Z7 -> 0 | AK7: =Saisie!AA7 -> 0 | AL7: =Saisie!AB7 -> 0 | AM7: =Saisie!AC7 -> 0 | AN7: =Saisie!AD7 -> 0 | ... AP7: =Saisie!AF7 -> 0 | AQ7: {=_xlfn.IFS(Saisie!AG7="OUI",1,Saisie!AG7="NON",0)} -> #N/A | AR7: {=_xlfn.IFS(Saisie!AH7="OUI",1,Saisie!AH7="NON",0)} -> #N/A | AS7: =Saisie!AI7 -> 0 | AT7: {=_xlfn.IFS(Saisie!AJ7="OUI",1,Saisie!AJ7="NON",0)} -> #N/A | AU7: =Saisie!AK7 -> 0 | AV7: {=_xlfn.IFS(Saisie!AL7="OUI",1,Saisie!AL7="NON",0)} -> #N/A | AW7: =Saisie!AM7 -> 0 | AX7: =Saisie!AN7 -> 0 | AY7: =Saisie!AO7 -> 0 | AZ7: =Saisie!AP7 -> 0 | BA7: =Saisie!AQ7 -> 0 | BB7: =Saisie!AR7 -> 0 | BC7: =Saisie!AS7 -> 0 | BD7: =Saisie!AT7 -> 0 | BE7: {=_xlfn.IFS(Saisie!AU7="OUI",1,Saisie!AU7="NON",0)} -> #N/A | BF7: =Saisie!AV7 -> 0 | BG7: =Saisie!AW7 -> 0 | BH7: {=_xlfn.IFS(Saisie!AX7="OUI",1,Saisie!AX7="NON",0)} -> #N/A | BI7: =Saisie!AY7 -> 0 | BJ7: {=_xlfn.IFS(Saisie!AZ7="OUI",1,Saisie!AZ7="NON",0)} -> #N/A | BK7: {=_xlfn.IFS(Saisie!BA7="OUI",1,Saisie!BA7="NON",0)} -> #N/A | BL7: =Saisie!BB7 -> 0 | BM7: =Saisie!BC7 -> #REF!
A8: 2 | B8: =Saisie!B8 -> 0 | C8: =Saisie!C8 -> 0 | D8: =Saisie!D8 -> 0 | E8: =Saisie!E8 -> 0 | F8: =Saisie!F8 -> 0 | G8: =Saisie!G8 -> 0 | H8: =Saisie!I8 -> 0 | I8: =Saisie!J8 -> 0 | J8: =Saisie!K8 -> 0 | K8: =Saisie!L8 -> 0 | L8: =Saisie!#REF! -> #REF! | M8: {=_xlfn.IFS(Saisie!M8="OUI",1,Saisie!M8="NON",0)} -> #N/A | N8: =Saisie!#REF! -> #REF! | O8: =Saisie!#REF! -> #REF! | P8: =Saisie!N8 -> 0 | Q8: {=_xlfn.IFS(Saisie!#REF!="OUI",1,Saisie!#REF!="NON",0)} -> #REF! | R8: =Saisie!#REF! -> #REF! | S8: =Saisie!#REF! -> #REF! | T8: =Saisie!#REF! -> #REF! | U8: =Saisie!#REF! -> #REF! | V8: {=_xlfn.IFS(Saisie!#REF!="OUI",1,Saisie!#REF!="NON",0)} -> #REF! | W8: {=_xlfn.IFS(Saisie!O8="OUI",1,Saisie!O8="NON",0)} -> #N/A | X8: =Saisie!P8 -> 0 | Y8: =Saisie!H8 -> 0 | Z8: =Saisie!#REF! -> #REF! | AA8: =Saisie!Q8 -> 0 | AB8: {=_xlfn.IFS(Saisie!R8="OUI",1,Saisie!R8="NON",0)} -> #N/A | AC8: =Saisie!S8 -> 0 | AD8: {=_xlfn.IFS(Saisie!T8="OUI",1,Saisie!T8="NON",0)} -> #N/A | AE8: =Saisie!U8 -> 0 | AF8: 3 | AG8: =Saisie!W8 -> 0 | AH8: =Saisie!X8 -> 0 | AI8: =Saisie!Y8 -> 0 | AJ8: =Saisie!Z8 -> 0 | AK8: =Saisie!AA8 -> 0 | AL8: =Saisie!AB8 -> 0 | AM8: =Saisie!AC8 -> 0 | AN8: =Saisie!AD8 -> 0 | ... AP8: =Saisie!AF8 -> 0 | AQ8: {=_xlfn.IFS(Saisie!AG8="OUI",1,Saisie!AG8="NON",0)} -> #N/A | AR8: {=_xlfn.IFS(Saisie!AH8="OUI",1,Saisie!AH8="NON",0)} -> #N/A | AS8: =Saisie!AI8 -> 0 | AT8: {=_xlfn.IFS(Saisie!AJ8="OUI",1,Saisie!AJ8="NON",0)} -> #N/A | AU8: =Saisie!AK8 -> 0 | AV8: {=_xlfn.IFS(Saisie!AL8="OUI",1,Saisie!AL8="NON",0)} -> #N/A | AW8: =Saisie!AM8 -> 0 | AX8: =Saisie!AN8 -> 0 | AY8: =Saisie!AO8 -> 0 | AZ8: =Saisie!AP8 -> 0 | BA8: =Saisie!AQ8 -> 0 | BB8: =Saisie!AR8 -> 0 | BC8: =Saisie!AS8 -> 0 | BD8: =Saisie!AT8 -> 0 | BE8: {=_xlfn.IFS(Saisie!AU8="OUI",1,Saisie!AU8="NON",0)} -> #N/A | BF8: =Saisie!AV8 -> 0 | BG8: =Saisie!AW8 -> 0 | BH8: {=_xlfn.IFS(Saisie!AX8="OUI",1,Saisie!AX8="NON",0)} -> #N/A | BI8: =Saisie!AY8 -> 0 | BJ8: {=_xlfn.IFS(Saisie!AZ8="OUI",1,Saisie!AZ8="NON",0)} -> #N/A | BK8: {=_xlfn.IFS(Saisie!BA8="OUI",1,Saisie!BA8="NON",0)} -> #N/A | BL8: =Saisie!BB8 -> 0 | BM8: =Saisie!BC8 -> #REF!
A9: 3 | B9: =Saisie!B9 -> 0 | C9: =Saisie!C9 -> 0 | D9: =Saisie!D9 -> 0 | E9: =Saisie!E9 -> 0 | F9: =Saisie!F9 -> 0 | G9: =Saisie!G9 -> 0 | H9: =Saisie!I9 -> 0 | I9: =Saisie!J9 -> 0 | J9: =Saisie!K9 -> 0 | K9: =Saisie!L9 -> 0 | L9: =Saisie!#REF! -> #REF! | M9: {=_xlfn.IFS(Saisie!M9="OUI",1,Saisie!M9="NON",0)} -> #N/A | N9: =Saisie!#REF! -> #REF! | O9: =Saisie!#REF! -> #REF! | P9: =Saisie!N9 -> 0 | Q9: {=_xlfn.IFS(Saisie!#REF!="OUI",1,Saisie!#REF!="NON",0)} -> #REF! | R9: =Saisie!#REF! -> #REF! | S9: =Saisie!#REF! -> #REF! | T9: =Saisie!#REF! -> #REF! | U9: =Saisie!#REF! -> #REF! | V9: {=_xlfn.IFS(Saisie!#REF!="OUI",1,Saisie!#REF!="NON",0)} -> #REF! | W9: {=_xlfn.IFS(Saisie!O9="OUI",1,Saisie!O9="NON",0)} -> #N/A | X9: =Saisie!P9 -> 0 | Y9: =Saisie!H9 -> 0 | Z9: =Saisie!#REF! -> #REF! | AA9: =Saisie!Q9 -> 0 | AB9: {=_xlfn.IFS(Saisie!R9="OUI",1,Saisie!R9="NON",0)} -> #N/A | AC9: =Saisie!S9 -> 0 | AD9: {=_xlfn.IFS(Saisie!T9="OUI",1,Saisie!T9="NON",0)} -> #N/A | AE9: =Saisie!U9 -> 0 | AF9: 3 | AG9: =Saisie!W9 -> 0 | AH9: =Saisie!X9 -> 0 | AI9: =Saisie!Y9 -> 0 | AJ9: =Saisie!Z9 -> 0 | AK9: =Saisie!AA9 -> 0 | AL9: =Saisie!AB9 -> 0 | AM9: =Saisie!AC9 -> 0 | AN9: =Saisie!AD9 -> 0 | ... AP9: =Saisie!AF9 -> 0 | AQ9: {=_xlfn.IFS(Saisie!AG9="OUI",1,Saisie!AG9="NON",0)} -> #N/A | AR9: {=_xlfn.IFS(Saisie!AH9="OUI",1,Saisie!AH9="NON",0)} -> #N/A | AS9: =Saisie!AI9 -> 0 | AT9: {=_xlfn.IFS(Saisie!AJ9="OUI",1,Saisie!AJ9="NON",0)} -> #N/A | AU9: =Saisie!AK9 -> 0 | AV9: {=_xlfn.IFS(Saisie!AL9="OUI",1,Saisie!AL9="NON",0)} -> #N/A | AW9: =Saisie!AM9 -> 0 | AX9: =Saisie!AN9 -> 0 | AY9: =Saisie!AO9 -> 0 | AZ9: =Saisie!AP9 -> 0 | BA9: =Saisie!AQ9 -> 0 | BB9: =Saisie!AR9 -> 0 | BC9: =Saisie!AS9 -> 0 | BD9: =Saisie!AT9 -> 0 | BE9: {=_xlfn.IFS(Saisie!AU9="OUI",1,Saisie!AU9="NON",0)} -> #N/A | BF9: =Saisie!AV9 -> 0 | BG9: =Saisie!AW9 -> 0 | BH9: {=_xlfn.IFS(Saisie!AX9="OUI",1,Saisie!AX9="NON",0)} -> #N/A | BI9: =Saisie!AY9 -> 0 | BJ9: {=_xlfn.IFS(Saisie!AZ9="OUI",1,Saisie!AZ9="NON",0)} -> #N/A | BK9: {=_xlfn.IFS(Saisie!BA9="OUI",1,Saisie!BA9="NON",0)} -> #N/A | BL9: =Saisie!BB9 -> 0 | BM9: =Saisie!BC9 -> #REF!
A10: 4 | B10: =Saisie!B10 -> 0 | C10: =Saisie!C10 -> 0 | D10: =Saisie!D10 -> 0 | E10: =Saisie!E10 -> 0 | F10: =Saisie!F10 -> 0 | G10: =Saisie!G10 -> 0 | H10: =Saisie!I10 -> 0 | I10: =Saisie!J10 -> 0 | J10: =Saisie!K10 -> 0 | K10: =Saisie!L10 -> 0 | L10: =Saisie!#REF! -> #REF! | M10: {=_xlfn.IFS(Saisie!M10="OUI",1,Saisie!M10="NON",0)} -> #N/A | N10: =Saisie!#REF! -> #REF! | O10: =Saisie!#REF! -> #REF! | P10: =Saisie!N10 -> 0 | Q10: {=_xlfn.IFS(Saisie!#REF!="OUI",1,Saisie!#REF!="NON",0)} -> #REF! | R10: =Saisie!#REF! -> #REF! | S10: =Saisie!#REF! -> #REF! | T10: =Saisie!#REF! -> #REF! | U10: =Saisie!#REF! -> #REF! | V10: {=_xlfn.IFS(Saisie!#REF!="OUI",1,Saisie!#REF!="NON",0)} -> #REF! | W10: {=_xlfn.IFS(Saisie!O10="OUI",1,Saisie!O10="NON",0)} -> #N/A | X10: =Saisie!P10 -> 0 | Y10: =Saisie!H10 -> 0 | Z10: =Saisie!#REF! -> #REF! | AA10: =Saisie!Q10 -> 0 | AB10: {=_xlfn.IFS(Saisie!R10="OUI",1,Saisie!R10="NON",0)} -> #N/A | AC10: =Saisie!S10 -> 0 | AD10: {=_xlfn.IFS(Saisie!T10="OUI",1,Saisie!T10="NON",0)} -> #N/A | AE10: =Saisie!U10 -> 0 | AF10: 3 | AG10: =Saisie!W10 -> 0 | AH10: =Saisie!X10 -> 0 | AI10: =Saisie!Y10 -> 0 | AJ10: =Saisie!Z10 -> 0 | AK10: =Saisie!AA10 -> 0 | AL10: =Saisie!AB10 -> 0 | AM10: =Saisie!AC10 -> 0 | AN10: =Saisie!AD10 -> 0 | ... AP10: =Saisie!AF10 -> 0 | AQ10: {=_xlfn.IFS(Saisie!AG10="OUI",1,Saisie!AG10="NON",0)} -> #N/A | AR10: {=_xlfn.IFS(Saisie!AH10="OUI",1,Saisie!AH10="NON",0)} -> #N/A | AS10: =Saisie!AI10 -> 0 | AT10: {=_xlfn.IFS(Saisie!AJ10="OUI",1,Saisie!AJ10="NON",0)} -> #N/A | AU10: =Saisie!AK10 -> 0 | AV10: {=_xlfn.IFS(Saisie!AL10="OUI",1,Saisie!AL10="NON",0)} -> #N/A | AW10: =Saisie!AM10 -> 0 | AX10: =Saisie!AN10 -> 0 | AY10: =Saisie!AO10 -> 0 | AZ10: =Saisie!AP10 -> 0 | BA10: =Saisie!AQ10 -> 0 | BB10: =Saisie!AR10 -> 0 | BC10: =Saisie!AS10 -> 0 | BD10: =Saisie!AT10 -> 0 | BE10: {=_xlfn.IFS(Saisie!AU10="OUI",1,Saisie!AU10="NON",0)} -> #N/A | BF10: =Saisie!AV10 -> 0 | BG10: =Saisie!AW10 -> 0 | BH10: {=_xlfn.IFS(Saisie!AX10="OUI",1,Saisie!AX10="NON",0)} -> #N/A | BI10: =Saisie!AY10 -> 0 | BJ10: {=_xlfn.IFS(Saisie!AZ10="OUI",1,Saisie!AZ10="NON",0)} -> #N/A | BK10: {=_xlfn.IFS(Saisie!BA10="OUI",1,Saisie!BA10="NON",0)} -> #N/A | BL10: =Saisie!BB10 -> 0 | BM10: =Saisie!BC10 -> #REF!
A11: 5 | B11: =Saisie!B11 -> 0 | C11: =Saisie!C11 -> 0 | D11: =Saisie!D11 -> 0 | E11: =Saisie!E11 -> 0 | F11: =Saisie!F11 -> 0 | G11: =Saisie!G11 -> 0 | H11: =Saisie!I11 -> 0 | I11: =Saisie!J11 -> 0 | J11: =Saisie!K11 -> 0 | K11: =Saisie!L11 -> 0 | L11: =Saisie!#REF! -> #REF! | M11: {=_xlfn.IFS(Saisie!M11="OUI",1,Saisie!M11="NON",0)} -> #N/A | N11: =Saisie!#REF! -> #REF! | O11: =Saisie!#REF! -> #REF! | P11: =Saisie!N11 -> 0 | Q11: {=_xlfn.IFS(Saisie!#REF!="OUI",1,Saisie!#REF!="NON",0)} -> #REF! | R11: =Saisie!#REF! -> #REF! | S11: =Saisie!#REF! -> #REF! | T11: =Saisie!#REF! -> #REF! | U11: =Saisie!#REF! -> #REF! | V11: {=_xlfn.IFS(Saisie!#REF!="OUI",1,Saisie!#REF!="NON",0)} -> #REF! | W11: {=_xlfn.IFS(Saisie!O11="OUI",1,Saisie!O11="NON",0)} -> #N/A | X11: =Saisie!P11 -> 0 | Y11: =Saisie!H11 -> 0 | Z11: =Saisie!#REF! -> #REF! | AA11: =Saisie!Q11 -> 0 | AB11: {=_xlfn.IFS(Saisie!R11="OUI",1,Saisie!R11="NON",0)} -> #N/A | AC11: =Saisie!S11 -> 0 | AD11: {=_xlfn.IFS(Saisie!T11="OUI",1,Saisie!T11="NON",0)} -> #N/A | AE11: =Saisie!U11 -> 0 | AF11: 3 | AG11: =Saisie!W11 -> 0 | AH11: =Saisie!X11 -> 0 | AI11: =Saisie!Y11 -> 0 | AJ11: =Saisie!Z11 -> 0 | AK11: =Saisie!AA11 -> 0 | AL11: =Saisie!AB11 -> 0 | AM11: =Saisie!AC11 -> 0 | AN11: =Saisie!AD11 -> 0 | ... AP11: =Saisie!AF11 -> 0 | AQ11: {=_xlfn.IFS(Saisie!AG11="OUI",1,Saisie!AG11="NON",0)} -> #N/A | AR11: {=_xlfn.IFS(Saisie!AH11="OUI",1,Saisie!AH11="NON",0)} -> #N/A | AS11: =Saisie!AI11 -> 0 | AT11: {=_xlfn.IFS(Saisie!AJ11="OUI",1,Saisie!AJ11="NON",0)} -> #N/A | AU11: =Saisie!AK11 -> 0 | AV11: {=_xlfn.IFS(Saisie!AL11="OUI",1,Saisie!AL11="NON",0)} -> #N/A | AW11: =Saisie!AM11 -> 0 | AX11: =Saisie!AN11 -> 0 | AY11: =Saisie!AO11 -> 0 | AZ11: =Saisie!AP11 -> 0 | BA11: =Saisie!AQ11 -> 0 | BB11: =Saisie!AR11 -> 0 | BC11: =Saisie!AS11 -> 0 | BD11: =Saisie!AT11 -> 0 | BE11: {=_xlfn.IFS(Saisie!AU11="OUI",1,Saisie!AU11="NON",0)} -> #N/A | BF11: =Saisie!AV11 -> 0 | BG11: =Saisie!AW11 -> 0 | BH11: {=_xlfn.IFS(Saisie!AX11="OUI",1,Saisie!AX11="NON",0)} -> #N/A | BI11: =Saisie!AY11 -> 0 | BJ11: {=_xlfn.IFS(Saisie!AZ11="OUI",1,Saisie!AZ11="NON",0)} -> #N/A | BK11: {=_xlfn.IFS(Saisie!BA11="OUI",1,Saisie!BA11="NON",0)} -> #N/A | BL11: =Saisie!BB11 -> 0 | BM11: =Saisie!BC11 -> #REF!
A12: 6 | B12: =Saisie!B12 -> 0 | C12: =Saisie!C12 -> 0 | D12: =Saisie!D12 -> 0 | E12: =Saisie!E12 -> 0 | F12: =Saisie!F12 -> 0 | G12: =Saisie!G12 -> 0 | H12: =Saisie!I12 -> 0 | I12: =Saisie!J12 -> 0 | J12: =Saisie!K12 -> 0 | K12: =Saisie!L12 -> 0 | L12: =Saisie!#REF! -> #REF! | M12: {=_xlfn.IFS(Saisie!M12="OUI",1,Saisie!M12="NON",0)} -> #N/A | N12: =Saisie!#REF! -> #REF! | O12: =Saisie!#REF! -> #REF! | P12: =Saisie!N12 -> 0 | Q12: {=_xlfn.IFS(Saisie!#REF!="OUI",1,Saisie!#REF!="NON",0)} -> #REF! | R12: =Saisie!#REF! -> #REF! | S12: =Saisie!#REF! -> #REF! | T12: =Saisie!#REF! -> #REF! | U12: =Saisie!#REF! -> #REF! | V12: {=_xlfn.IFS(Saisie!#REF!="OUI",1,Saisie!#REF!="NON",0)} -> #REF! | W12: {=_xlfn.IFS(Saisie!O12="OUI",1,Saisie!O12="NON",0)} -> #N/A | X12: =Saisie!P12 -> 0 | Y12: =Saisie!H12 -> 0 | Z12: =Saisie!#REF! -> #REF! | AA12: =Saisie!Q12 -> 0 | AB12: {=_xlfn.IFS(Saisie!R12="OUI",1,Saisie!R12="NON",0)} -> #N/A | AC12: =Saisie!S12 -> 0 | AD12: {=_xlfn.IFS(Saisie!T12="OUI",1,Saisie!T12="NON",0)} -> #N/A | AE12: =Saisie!U12 -> 0 | AF12: 3 | AG12: =Saisie!W12 -> 0 | AH12: =Saisie!X12 -> 0 | AI12: =Saisie!Y12 -> 0 | AJ12: =Saisie!Z12 -> 0 | AK12: =Saisie!AA12 -> 0 | AL12: =Saisie!AB12 -> 0 | AM12: =Saisie!AC12 -> 0 | AN12: =Saisie!AD12 -> 0 | ... AP12: =Saisie!AF12 -> 0 | AQ12: {=_xlfn.IFS(Saisie!AG12="OUI",1,Saisie!AG12="NON",0)} -> #N/A | AR12: {=_xlfn.IFS(Saisie!AH12="OUI",1,Saisie!AH12="NON",0)} -> #N/A | AS12: =Saisie!AI12 -> 0 | AT12: {=_xlfn.IFS(Saisie!AJ12="OUI",1,Saisie!AJ12="NON",0)} -> #N/A | AU12: =Saisie!AK12 -> 0 | AV12: {=_xlfn.IFS(Saisie!AL12="OUI",1,Saisie!AL12="NON",0)} -> #N/A | AW12: =Saisie!AM12 -> 0 | AX12: =Saisie!AN12 -> 0 | AY12: =Saisie!AO12 -> 0 | AZ12: =Saisie!AP12 -> 0 | BA12: =Saisie!AQ12 -> 0 | BB12: =Saisie!AR12 -> 0 | BC12: =Saisie!AS12 -> 0 | BD12: =Saisie!AT12 -> 0 | BE12: {=_xlfn.IFS(Saisie!AU12="OUI",1,Saisie!AU12="NON",0)} -> #N/A | BF12: =Saisie!AV12 -> 0 | BG12: =Saisie!AW12 -> 0 | BH12: {=_xlfn.IFS(Saisie!AX12="OUI",1,Saisie!AX12="NON",0)} -> #N/A | BI12: =Saisie!AY12 -> 0 | BJ12: {=_xlfn.IFS(Saisie!AZ12="OUI",1,Saisie!AZ12="NON",0)} -> #N/A | BK12: {=_xlfn.IFS(Saisie!BA12="OUI",1,Saisie!BA12="NON",0)} -> #N/A | BL12: =Saisie!BB12 -> 0 | BM12: =Saisie!BC12 -> #REF!
A13: 7 | B13: =Saisie!B13 -> 0 | C13: =Saisie!C13 -> 0 | D13: =Saisie!D13 -> 0 | E13: =Saisie!E13 -> 0 | F13: =Saisie!F13 -> 0 | G13: =Saisie!G13 -> 0 | H13: =Saisie!I13 -> 0 | I13: =Saisie!J13 -> 0 | J13: =Saisie!K13 -> 0 | K13: =Saisie!L13 -> 0 | L13: =Saisie!#REF! -> #REF! | M13: {=_xlfn.IFS(Saisie!M13="OUI",1,Saisie!M13="NON",0)} -> #N/A | N13: =Saisie!#REF! -> #REF! | O13: =Saisie!#REF! -> #REF! | P13: =Saisie!N13 -> 0 | Q13: {=_xlfn.IFS(Saisie!#REF!="OUI",1,Saisie!#REF!="NON",0)} -> #REF! | R13: =Saisie!#REF! -> #REF! | S13: =Saisie!#REF! -> #REF! | T13: =Saisie!#REF! -> #REF! | U13: =Saisie!#REF! -> #REF! | V13: {=_xlfn.IFS(Saisie!#REF!="OUI",1,Saisie!#REF!="NON",0)} -> #REF! | W13: {=_xlfn.IFS(Saisie!O13="OUI",1,Saisie!O13="NON",0)} -> #N/A | X13: =Saisie!P13 -> 0 | Y13: =Saisie!H13 -> 0 | Z13: =Saisie!#REF! -> #REF! | AA13: =Saisie!Q13 -> 0 | AB13: {=_xlfn.IFS(Saisie!R13="OUI",1,Saisie!R13="NON",0)} -> #N/A | AC13: =Saisie!S13 -> 0 | AD13: {=_xlfn.IFS(Saisie!T13="OUI",1,Saisie!T13="NON",0)} -> #N/A | AE13: =Saisie!U13 -> 0 | AF13: 3 | AG13: =Saisie!W13 -> 0 | AH13: =Saisie!X13 -> 0 | AI13: =Saisie!Y13 -> 0 | AJ13: =Saisie!Z13 -> 0 | AK13: =Saisie!AA13 -> 0 | AL13: =Saisie!AB13 -> 0 | AM13: =Saisie!AC13 -> 0 | AN13: =Saisie!AD13 -> 0 | ... AP13: =Saisie!AF13 -> 0 | AQ13: {=_xlfn.IFS(Saisie!AG13="OUI",1,Saisie!AG13="NON",0)} -> #N/A | AR13: {=_xlfn.IFS(Saisie!AH13="OUI",1,Saisie!AH13="NON",0)} -> #N/A | AS13: =Saisie!AI13 -> 0 | AT13: {=_xlfn.IFS(Saisie!AJ13="OUI",1,Saisie!AJ13="NON",0)} -> #N/A | AU13: =Saisie!AK13 -> 0 | AV13: {=_xlfn.IFS(Saisie!AL13="OUI",1,Saisie!AL13="NON",0)} -> #N/A | AW13: =Saisie!AM13 -> 0 | AX13: =Saisie!AN13 -> 0 | AY13: =Saisie!AO13 -> 0 | AZ13: =Saisie!AP13 -> 0 | BA13: =Saisie!AQ13 -> 0 | BB13: =Saisie!AR13 -> 0 | BC13: =Saisie!AS13 -> 0 | BD13: =Saisie!AT13 -> 0 | BE13: {=_xlfn.IFS(Saisie!AU13="OUI",1,Saisie!AU13="NON",0)} -> #N/A | BF13: =Saisie!AV13 -> 0 | BG13: =Saisie!AW13 -> 0 | BH13: {=_xlfn.IFS(Saisie!AX13="OUI",1,Saisie!AX13="NON",0)} -> #N/A | BI13: =Saisie!AY13 -> 0 | BJ13: {=_xlfn.IFS(Saisie!AZ13="OUI",1,Saisie!AZ13="NON",0)} -> #N/A | BK13: {=_xlfn.IFS(Saisie!BA13="OUI",1,Saisie!BA13="NON",0)} -> #N/A | BL13: =Saisie!BB13 -> 0 | BM13: =Saisie!BC13 -> #REF!
A14: 8 | B14: =Saisie!B14 -> 0 | C14: =Saisie!C14 -> 0 | D14: =Saisie!D14 -> 0 | E14: =Saisie!E14 -> 0 | F14: =Saisie!F14 -> 0 | G14: =Saisie!G14 -> 0 | H14: =Saisie!I14 -> 0 | I14: =Saisie!J14 -> 0 | J14: =Saisie!K14 -> 0 | K14: =Saisie!L14 -> 0 | L14: =Saisie!#REF! -> #REF! | M14: {=_xlfn.IFS(Saisie!M14="OUI",1,Saisie!M14="NON",0)} -> #N/A | N14: =Saisie!#REF! -> #REF! | O14: =Saisie!#REF! -> #REF! | P14: =Saisie!N14 -> 0 | Q14: {=_xlfn.IFS(Saisie!#REF!="OUI",1,Saisie!#REF!="NON",0)} -> #REF! | R14: =Saisie!#REF! -> #REF! | S14: =Saisie!#REF! -> #REF! | T14: =Saisie!#REF! -> #REF! | U14: =Saisie!#REF! -> #REF! | V14: {=_xlfn.IFS(Saisie!#REF!="OUI",1,Saisie!#REF!="NON",0)} -> #REF! | W14: {=_xlfn.IFS(Saisie!O14="OUI",1,Saisie!O14="NON",0)} -> #N/A | X14: =Saisie!P14 -> 0 | Y14: =Saisie!H14 -> 0 | Z14: =Saisie!#REF! -> #REF! | AA14: =Saisie!Q14 -> 0 | AB14: {=_xlfn.IFS(Saisie!R14="OUI",1,Saisie!R14="NON",0)} -> #N/A | AC14: =Saisie!S14 -> 0 | AD14: {=_xlfn.IFS(Saisie!T14="OUI",1,Saisie!T14="NON",0)} -> #N/A | AE14: =Saisie!U14 -> 0 | AF14: 3 | AG14: =Saisie!W14 -> 0 | AH14: =Saisie!X14 -> 0 | AI14: =Saisie!Y14 -> 0 | AJ14: =Saisie!Z14 -> 0 | AK14: =Saisie!AA14 -> 0 | AL14: =Saisie!AB14 -> 0 | AM14: =Saisie!AC14 -> 0 | AN14: =Saisie!AD14 -> 0 | ... AP14: =Saisie!AF14 -> 0 | AQ14: {=_xlfn.IFS(Saisie!AG14="OUI",1,Saisie!AG14="NON",0)} -> #N/A | AR14: {=_xlfn.IFS(Saisie!AH14="OUI",1,Saisie!AH14="NON",0)} -> #N/A | AS14: =Saisie!AI14 -> 0 | AT14: {=_xlfn.IFS(Saisie!AJ14="OUI",1,Saisie!AJ14="NON",0)} -> #N/A | AU14: =Saisie!AK14 -> 0 | AV14: {=_xlfn.IFS(Saisie!AL14="OUI",1,Saisie!AL14="NON",0)} -> #N/A | AW14: =Saisie!AM14 -> 0 | AX14: =Saisie!AN14 -> 0 | AY14: =Saisie!AO14 -> 0 | AZ14: =Saisie!AP14 -> 0 | BA14: =Saisie!AQ14 -> 0 | BB14: =Saisie!AR14 -> 0 | BC14: =Saisie!AS14 -> 0 | BD14: =Saisie!AT14 -> 0 | BE14: {=_xlfn.IFS(Saisie!AU14="OUI",1,Saisie!AU14="NON",0)} -> #N/A | BF14: =Saisie!AV14 -> 0 | BG14: =Saisie!AW14 -> 0 | BH14: {=_xlfn.IFS(Saisie!AX14="OUI",1,Saisie!AX14="NON",0)} -> #N/A | BI14: =Saisie!AY14 -> 0 | BJ14: {=_xlfn.IFS(Saisie!AZ14="OUI",1,Saisie!AZ14="NON",0)} -> #N/A | BK14: {=_xlfn.IFS(Saisie!BA14="OUI",1,Saisie!BA14="NON",0)} -> #N/A | BL14: =Saisie!BB14 -> 0 | BM14: =Saisie!BC14 -> #REF!
A15: 9 | B15: =Saisie!B15 -> 0 | C15: =Saisie!C15 -> 0 | D15: =Saisie!D15 -> 0 | E15: =Saisie!E15 -> 0 | F15: =Saisie!F15 -> 0 | G15: =Saisie!G15 -> 0 | H15: =Saisie!I15 -> 0 | I15: =Saisie!J15 -> 0 | J15: =Saisie!K15 -> 0 | K15: =Saisie!L15 -> 0 | L15: =Saisie!#REF! -> #REF! | M15: {=_xlfn.IFS(Saisie!M15="OUI",1,Saisie!M15="NON",0)} -> #N/A | N15: =Saisie!#REF! -> #REF! | O15: =Saisie!#REF! -> #REF! | P15: =Saisie!N15 -> 0 | Q15: {=_xlfn.IFS(Saisie!#REF!="OUI",1,Saisie!#REF!="NON",0)} -> #REF! | R15: =Saisie!#REF! -> #REF! | S15: =Saisie!#REF! -> #REF! | T15: =Saisie!#REF! -> #REF! | U15: =Saisie!#REF! -> #REF! | V15: {=_xlfn.IFS(Saisie!#REF!="OUI",1,Saisie!#REF!="NON",0)} -> #REF! | W15: {=_xlfn.IFS(Saisie!O15="OUI",1,Saisie!O15="NON",0)} -> #N/A | X15: =Saisie!P15 -> 0 | Y15: =Saisie!H15 -> 0 | Z15: =Saisie!#REF! -> #REF! | AA15: =Saisie!Q15 -> 0 | AB15: {=_xlfn.IFS(Saisie!R15="OUI",1,Saisie!R15="NON",0)} -> #N/A | AC15: =Saisie!S15 -> 0 | AD15: {=_xlfn.IFS(Saisie!T15="OUI",1,Saisie!T15="NON",0)} -> #N/A | AE15: =Saisie!U15 -> 0 | AF15: 3 | AG15: =Saisie!W15 -> 0 | AH15: =Saisie!X15 -> 0 | AI15: =Saisie!Y15 -> 0 | AJ15: =Saisie!Z15 -> 0 | AK15: =Saisie!AA15 -> 0 | AL15: =Saisie!AB15 -> 0 | AM15: =Saisie!AC15 -> 0 | AN15: =Saisie!AD15 -> 0 | ... AP15: =Saisie!AF15 -> 0 | AQ15: {=_xlfn.IFS(Saisie!AG15="OUI",1,Saisie!AG15="NON",0)} -> #N/A | AR15: {=_xlfn.IFS(Saisie!AH15="OUI",1,Saisie!AH15="NON",0)} -> #N/A | AS15: =Saisie!AI15 -> 0 | AT15: {=_xlfn.IFS(Saisie!AJ15="OUI",1,Saisie!AJ15="NON",0)} -> #N/A | AU15: =Saisie!AK15 -> 0 | AV15: {=_xlfn.IFS(Saisie!AL15="OUI",1,Saisie!AL15="NON",0)} -> #N/A | AW15: =Saisie!AM15 -> 0 | AX15: =Saisie!AN15 -> 0 | AY15: =Saisie!AO15 -> 0 | AZ15: =Saisie!AP15 -> 0 | BA15: =Saisie!AQ15 -> 0 | BB15: =Saisie!AR15 -> 0 | BC15: =Saisie!AS15 -> 0 | BD15: =Saisie!AT15 -> 0 | BE15: {=_xlfn.IFS(Saisie!AU15="OUI",1,Saisie!AU15="NON",0)} -> #N/A | BF15: =Saisie!AV15 -> 0 | BG15: =Saisie!AW15 -> 0 | BH15: {=_xlfn.IFS(Saisie!AX15="OUI",1,Saisie!AX15="NON",0)} -> #N/A | BI15: =Saisie!AY15 -> 0 | BJ15: {=_xlfn.IFS(Saisie!AZ15="OUI",1,Saisie!AZ15="NON",0)} -> #N/A | BK15: {=_xlfn.IFS(Saisie!BA15="OUI",1,Saisie!BA15="NON",0)} -> #N/A | BL15: =Saisie!BB15 -> 0 | BM15: =Saisie!BC15 -> #REF!
A16: 10 | B16: =Saisie!B16 -> 0 | C16: =Saisie!C16 -> 0 | D16: =Saisie!D16 -> 0 | E16: =Saisie!E16 -> 0 | F16: =Saisie!F16 -> 0 | G16: =Saisie!G16 -> 0 | H16: =Saisie!I16 -> 0 | I16: =Saisie!J16 -> 0 | J16: =Saisie!K16 -> 0 | K16: =Saisie!L16 -> 0 | L16: =Saisie!#REF! -> #REF! | M16: {=_xlfn.IFS(Saisie!M16="OUI",1,Saisie!M16="NON",0)} -> #N/A | N16: =Saisie!#REF! -> #REF! | O16: =Saisie!#REF! -> #REF! | P16: =Saisie!N16 -> 0 | Q16: {=_xlfn.IFS(Saisie!#REF!="OUI",1,Saisie!#REF!="NON",0)} -> #REF! | R16: =Saisie!#REF! -> #REF! | S16: =Saisie!#REF! -> #REF! | T16: =Saisie!#REF! -> #REF! | U16: =Saisie!#REF! -> #REF! | V16: {=_xlfn.IFS(Saisie!#REF!="OUI",1,Saisie!#REF!="NON",0)} -> #REF! | W16: {=_xlfn.IFS(Saisie!O16="OUI",1,Saisie!O16="NON",0)} -> #N/A | X16: =Saisie!P16 -> 0 | Y16: =Saisie!H16 -> 0 | Z16: =Saisie!#REF! -> #REF! | AA16: =Saisie!Q16 -> 0 | AB16: {=_xlfn.IFS(Saisie!R16="OUI",1,Saisie!R16="NON",0)} -> #N/A | AC16: =Saisie!S16 -> 0 | AD16: {=_xlfn.IFS(Saisie!T16="OUI",1,Saisie!T16="NON",0)} -> #N/A | AE16: =Saisie!U16 -> 0 | AF16: 3 | AG16: =Saisie!W16 -> 0 | AH16: =Saisie!X16 -> 0 | AI16: =Saisie!Y16 -> 0 | AJ16: =Saisie!Z16 -> 0 | AK16: =Saisie!AA16 -> 0 | AL16: =Saisie!AB16 -> 0 | AM16: =Saisie!AC16 -> 0 | AN16: =Saisie!AD16 -> 0 | ... AP16: =Saisie!AF16 -> 0 | AQ16: {=_xlfn.IFS(Saisie!AG16="OUI",1,Saisie!AG16="NON",0)} -> #N/A | AR16: {=_xlfn.IFS(Saisie!AH16="OUI",1,Saisie!AH16="NON",0)} -> #N/A | AS16: =Saisie!AI16 -> 0 | AT16: {=_xlfn.IFS(Saisie!AJ16="OUI",1,Saisie!AJ16="NON",0)} -> #N/A | AU16: =Saisie!AK16 -> 0 | AV16: {=_xlfn.IFS(Saisie!AL16="OUI",1,Saisie!AL16="NON",0)} -> #N/A | AW16: =Saisie!AM16 -> 0 | AX16: =Saisie!AN16 -> 0 | AY16: =Saisie!AO16 -> 0 | AZ16: =Saisie!AP16 -> 0 | BA16: =Saisie!AQ16 -> 0 | BB16: =Saisie!AR16 -> 0 | BC16: =Saisie!AS16 -> 0 | BD16: =Saisie!AT16 -> 0 | BE16: {=_xlfn.IFS(Saisie!AU16="OUI",1,Saisie!AU16="NON",0)} -> #N/A | BF16: =Saisie!AV16 -> 0 | BG16: =Saisie!AW16 -> 0 | BH16: {=_xlfn.IFS(Saisie!AX16="OUI",1,Saisie!AX16="NON",0)} -> #N/A | BI16: =Saisie!AY16 -> 0 | BJ16: {=_xlfn.IFS(Saisie!AZ16="OUI",1,Saisie!AZ16="NON",0)} -> #N/A | BK16: {=_xlfn.IFS(Saisie!BA16="OUI",1,Saisie!BA16="NON",0)} -> #N/A | BL16: =Saisie!BB16 -> 0 | BM16: =Saisie!BC16 -> #REF!
A17: 11 | B17: =Saisie!B17 -> 0 | C17: =Saisie!C17 -> 0 | D17: =Saisie!D17 -> 0 | E17: =Saisie!E17 -> 0 | F17: =Saisie!F17 -> 0 | G17: =Saisie!G17 -> 0 | H17: =Saisie!I17 -> 0 | I17: =Saisie!J17 -> 0 | J17: =Saisie!K17 -> 0 | K17: =Saisie!L17 -> 0 | L17: =Saisie!#REF! -> #REF! | M17: {=_xlfn.IFS(Saisie!M17="OUI",1,Saisie!M17="NON",0)} -> #N/A | N17: =Saisie!#REF! -> #REF! | O17: =Saisie!#REF! -> #REF! | P17: =Saisie!N17 -> 0 | Q17: {=_xlfn.IFS(Saisie!#REF!="OUI",1,Saisie!#REF!="NON",0)} -> #REF! | R17: =Saisie!#REF! -> #REF! | S17: =Saisie!#REF! -> #REF! | T17: =Saisie!#REF! -> #REF! | U17: =Saisie!#REF! -> #REF! | V17: {=_xlfn.IFS(Saisie!#REF!="OUI",1,Saisie!#REF!="NON",0)} -> #REF! | W17: {=_xlfn.IFS(Saisie!O17="OUI",1,Saisie!O17="NON",0)} -> #N/A | X17: =Saisie!P17 -> 0 | Y17: =Saisie!H17 -> 0 | Z17: =Saisie!#REF! -> #REF! | AA17: =Saisie!Q17 -> 0 | AB17: {=_xlfn.IFS(Saisie!R17="OUI",1,Saisie!R17="NON",0)} -> #N/A | AC17: =Saisie!S17 -> 0 | AD17: {=_xlfn.IFS(Saisie!T17="OUI",1,Saisie!T17="NON",0)} -> #N/A | AE17: =Saisie!U17 -> 0 | AF17: 3 | AG17: =Saisie!W17 -> 0 | AH17: =Saisie!X17 -> 0 | AI17: =Saisie!Y17 -> 0 | AJ17: =Saisie!Z17 -> 0 | AK17: =Saisie!AA17 -> 0 | AL17: =Saisie!AB17 -> 0 | AM17: =Saisie!AC17 -> 0 | AN17: =Saisie!AD17 -> 0 | ... AP17: =Saisie!AF17 -> 0 | AQ17: {=_xlfn.IFS(Saisie!AG17="OUI",1,Saisie!AG17="NON",0)} -> #N/A | AR17: {=_xlfn.IFS(Saisie!AH17="OUI",1,Saisie!AH17="NON",0)} -> #N/A | AS17: =Saisie!AI17 -> 0 | AT17: {=_xlfn.IFS(Saisie!AJ17="OUI",1,Saisie!AJ17="NON",0)} -> #N/A | AU17: =Saisie!AK17 -> 0 | AV17: {=_xlfn.IFS(Saisie!AL17="OUI",1,Saisie!AL17="NON",0)} -> #N/A | AW17: =Saisie!AM17 -> 0 | AX17: =Saisie!AN17 -> 0 | AY17: =Saisie!AO17 -> 0 | AZ17: =Saisie!AP17 -> 0 | BA17: =Saisie!AQ17 -> 0 | BB17: =Saisie!AR17 -> 0 | BC17: =Saisie!AS17 -> 0 | BD17: =Saisie!AT17 -> 0 | BE17: {=_xlfn.IFS(Saisie!AU17="OUI",1,Saisie!AU17="NON",0)} -> #N/A | BF17: =Saisie!AV17 -> 0 | BG17: =Saisie!AW17 -> 0 | BH17: {=_xlfn.IFS(Saisie!AX17="OUI",1,Saisie!AX17="NON",0)} -> #N/A | BI17: =Saisie!AY17 -> 0 | BJ17: {=_xlfn.IFS(Saisie!AZ17="OUI",1,Saisie!AZ17="NON",0)} -> #N/A | BK17: {=_xlfn.IFS(Saisie!BA17="OUI",1,Saisie!BA17="NON",0)} -> #N/A | BL17: =Saisie!BB17 -> 0 | BM17: =Saisie!BC17 -> #REF!
A18: 12 | B18: =Saisie!B18 -> 0 | C18: =Saisie!C18 -> 0 | D18: =Saisie!D18 -> 0 | E18: =Saisie!E18 -> 0 | F18: =Saisie!F18 -> 0 | G18: =Saisie!G18 -> 0 | H18: =Saisie!I18 -> 0 | I18: =Saisie!J18 -> 0 | J18: =Saisie!K18 -> 0 | K18: =Saisie!L18 -> 0 | L18: =Saisie!#REF! -> #REF! | M18: {=_xlfn.IFS(Saisie!M18="OUI",1,Saisie!M18="NON",0)} -> #N/A | N18: =Saisie!#REF! -> #REF! | O18: =Saisie!#REF! -> #REF! | P18: =Saisie!N18 -> 0 | Q18: {=_xlfn.IFS(Saisie!#REF!="OUI",1,Saisie!#REF!="NON",0)} -> #REF! | R18: =Saisie!#REF! -> #REF! | S18: =Saisie!#REF! -> #REF! | T18: =Saisie!#REF! -> #REF! | U18: =Saisie!#REF! -> #REF! | V18: {=_xlfn.IFS(Saisie!#REF!="OUI",1,Saisie!#REF!="NON",0)} -> #REF! | W18: {=_xlfn.IFS(Saisie!O18="OUI",1,Saisie!O18="NON",0)} -> #N/A | X18: =Saisie!P18 -> 0 | Y18: =Saisie!H18 -> 0 | Z18: =Saisie!#REF! -> #REF! | AA18: =Saisie!Q18 -> 0 | AB18: {=_xlfn.IFS(Saisie!R18="OUI",1,Saisie!R18="NON",0)} -> #N/A | AC18: =Saisie!S18 -> 0 | AD18: {=_xlfn.IFS(Saisie!T18="OUI",1,Saisie!T18="NON",0)} -> #N/A | AE18: =Saisie!U18 -> 0 | AF18: 3 | AG18: =Saisie!W18 -> 0 | AH18: =Saisie!X18 -> 0 | AI18: =Saisie!Y18 -> 0 | AJ18: =Saisie!Z18 -> 0 | AK18: =Saisie!AA18 -> 0 | AL18: =Saisie!AB18 -> 0 | AM18: =Saisie!AC18 -> 0 | AN18: =Saisie!AD18 -> 0 | ... AP18: =Saisie!AF18 -> 0 | AQ18: {=_xlfn.IFS(Saisie!AG18="OUI",1,Saisie!AG18="NON",0)} -> #N/A | AR18: {=_xlfn.IFS(Saisie!AH18="OUI",1,Saisie!AH18="NON",0)} -> #N/A | AS18: =Saisie!AI18 -> 0 | AT18: {=_xlfn.IFS(Saisie!AJ18="OUI",1,Saisie!AJ18="NON",0)} -> #N/A | AU18: =Saisie!AK18 -> 0 | AV18: {=_xlfn.IFS(Saisie!AL18="OUI",1,Saisie!AL18="NON",0)} -> #N/A | AW18: =Saisie!AM18 -> 0 | AX18: =Saisie!AN18 -> 0 | AY18: =Saisie!AO18 -> 0 | AZ18: =Saisie!AP18 -> 0 | BA18: =Saisie!AQ18 -> 0 | BB18: =Saisie!AR18 -> 0 | BC18: =Saisie!AS18 -> 0 | BD18: =Saisie!AT18 -> 0 | BE18: {=_xlfn.IFS(Saisie!AU18="OUI",1,Saisie!AU18="NON",0)} -> #N/A | BF18: =Saisie!AV18 -> 0 | BG18: =Saisie!AW18 -> 0 | BH18: {=_xlfn.IFS(Saisie!AX18="OUI",1,Saisie!AX18="NON",0)} -> #N/A | BI18: =Saisie!AY18 -> 0 | BJ18: {=_xlfn.IFS(Saisie!AZ18="OUI",1,Saisie!AZ18="NON",0)} -> #N/A | BK18: {=_xlfn.IFS(Saisie!BA18="OUI",1,Saisie!BA18="NON",0)} -> #N/A | BL18: =Saisie!BB18 -> 0 | BM18: =Saisie!BC18 -> #REF!
... A23: 17 | B23: =Saisie!B23 -> 0 | C23: =Saisie!C23 -> 0 | D23: =Saisie!D23 -> 0 | E23: =Saisie!E23 -> 0 | F23: =Saisie!F23 -> 0 | G23: =Saisie!G23 -> 0 | H23: =Saisie!I23 -> 0 | I23: =Saisie!J23 -> 0 | J23: =Saisie!K23 -> 0 | K23: =Saisie!L23 -> 0 | L23: =Saisie!#REF! -> #REF! | M23: {=_xlfn.IFS(Saisie!M23="OUI",1,Saisie!M23="NON",0)} -> #N/A | N23: =Saisie!#REF! -> #REF! | O23: =Saisie!#REF! -> #REF! | P23: =Saisie!N23 -> 0 | Q23: {=_xlfn.IFS(Saisie!#REF!="OUI",1,Saisie!#REF!="NON",0)} -> #REF! | R23: =Saisie!#REF! -> #REF! | S23: =Saisie!#REF! -> #REF! | T23: =Saisie!#REF! -> #REF! | U23: =Saisie!#REF! -> #REF! | V23: {=_xlfn.IFS(Saisie!#REF!="OUI",1,Saisie!#REF!="NON",0)} -> #REF! | W23: {=_xlfn.IFS(Saisie!O23="OUI",1,Saisie!O23="NON",0)} -> #N/A | X23: =Saisie!P23 -> 0 | Y23: =Saisie!H23 -> 0 | Z23: =Saisie!#REF! -> #REF! | AA23: =Saisie!Q23 -> 0 | AB23: {=_xlfn.IFS(Saisie!R23="OUI",1,Saisie!R23="NON",0)} -> #N/A | AC23: =Saisie!S23 -> 0 | AD23: {=_xlfn.IFS(Saisie!T23="OUI",1,Saisie!T23="NON",0)} -> #N/A | AE23: =Saisie!U23 -> 0 | AF23: 3 | AG23: =Saisie!W23 -> 0 | AH23: =Saisie!X23 -> 0 | AI23: =Saisie!Y23 -> 0 | AJ23: =Saisie!Z23 -> 0 | AK23: =Saisie!AA23 -> 0 | AL23: =Saisie!AB23 -> 0 | AM23: =Saisie!AC23 -> 0 | AN23: =Saisie!AD23 -> 0 | ... AP23: =Saisie!AF23 -> 0 | AQ23: {=_xlfn.IFS(Saisie!AG23="OUI",1,Saisie!AG23="NON",0)} -> #N/A | AR23: {=_xlfn.IFS(Saisie!AH23="OUI",1,Saisie!AH23="NON",0)} -> #N/A | AS23: =Saisie!AI23 -> 0 | AT23: {=_xlfn.IFS(Saisie!AJ23="OUI",1,Saisie!AJ23="NON",0)} -> #N/A | AU23: =Saisie!AK23 -> 0 | AV23: {=_xlfn.IFS(Saisie!AL23="OUI",1,Saisie!AL23="NON",0)} -> #N/A | AW23: =Saisie!AM23 -> 0 | AX23: =Saisie!AN23 -> 0 | AY23: =Saisie!AO23 -> 0 | AZ23: =Saisie!AP23 -> 0 | BA23: =Saisie!AQ23 -> 0 | BB23: =Saisie!AR23 -> 0 | BC23: =Saisie!AS23 -> 0 | BD23: =Saisie!AT23 -> 0 | BE23: {=_xlfn.IFS(Saisie!AU23="OUI",1,Saisie!AU23="NON",0)} -> #N/A | BF23: =Saisie!AV23 -> 0 | BG23: =Saisie!AW23 -> 0 | BH23: {=_xlfn.IFS(Saisie!AX23="OUI",1,Saisie!AX23="NON",0)} -> #N/A | BI23: =Saisie!AY23 -> 0 | BJ23: {=_xlfn.IFS(Saisie!AZ23="OUI",1,Saisie!AZ23="NON",0)} -> #N/A | BK23: {=_xlfn.IFS(Saisie!BA23="OUI",1,Saisie!BA23="NON",0)} -> #N/A | BL23: =Saisie!BB23 -> 0 | BM23: =Saisie!BC23 -> #REF!
A24: 18 | B24: =Saisie!B24 -> 0 | C24: =Saisie!C24 -> 0 | D24: =Saisie!D24 -> 0 | E24: =Saisie!E24 -> 0 | F24: =Saisie!F24 -> 0 | G24: =Saisie!G24 -> 0 | H24: =Saisie!I24 -> 0 | I24: =Saisie!J24 -> 0 | J24: =Saisie!K24 -> 0 | K24: =Saisie!L24 -> 0 | L24: =Saisie!#REF! -> #REF! | M24: {=_xlfn.IFS(Saisie!M24="OUI",1,Saisie!M24="NON",0)} -> #N/A | N24: =Saisie!#REF! -> #REF! | O24: =Saisie!#REF! -> #REF! | P24: =Saisie!N24 -> 0 | Q24: {=_xlfn.IFS(Saisie!#REF!="OUI",1,Saisie!#REF!="NON",0)} -> #REF! | R24: =Saisie!#REF! -> #REF! | S24: =Saisie!#REF! -> #REF! | T24: =Saisie!#REF! -> #REF! | U24: =Saisie!#REF! -> #REF! | V24: {=_xlfn.IFS(Saisie!#REF!="OUI",1,Saisie!#REF!="NON",0)} -> #REF! | W24: {=_xlfn.IFS(Saisie!O24="OUI",1,Saisie!O24="NON",0)} -> #N/A | X24: =Saisie!P24 -> 0 | Y24: =Saisie!H24 -> 0 | Z24: =Saisie!#REF! -> #REF! | AA24: =Saisie!Q24 -> 0 | AB24: {=_xlfn.IFS(Saisie!R24="OUI",1,Saisie!R24="NON",0)} -> #N/A | AC24: =Saisie!S24 -> 0 | AD24: {=_xlfn.IFS(Saisie!T24="OUI",1,Saisie!T24="NON",0)} -> #N/A | AE24: =Saisie!U24 -> 0 | AF24: 3 | AG24: =Saisie!W24 -> 0 | AH24: =Saisie!X24 -> 0 | AI24: =Saisie!Y24 -> 0 | AJ24: =Saisie!Z24 -> 0 | AK24: =Saisie!AA24 -> 0 | AL24: =Saisie!AB24 -> 0 | AM24: =Saisie!AC24 -> 0 | AN24: =Saisie!AD24 -> 0 | ... AP24: =Saisie!AF24 -> 0 | AQ24: {=_xlfn.IFS(Saisie!AG24="OUI",1,Saisie!AG24="NON",0)} -> #N/A | AR24: {=_xlfn.IFS(Saisie!AH24="OUI",1,Saisie!AH24="NON",0)} -> #N/A | AS24: =Saisie!AI24 -> 0 | AT24: {=_xlfn.IFS(Saisie!AJ24="OUI",1,Saisie!AJ24="NON",0)} -> #N/A | AU24: =Saisie!AK24 -> 0 | AV24: {=_xlfn.IFS(Saisie!AL24="OUI",1,Saisie!AL24="NON",0)} -> #N/A | AW24: =Saisie!AM24 -> 0 | AX24: =Saisie!AN24 -> 0 | AY24: =Saisie!AO24 -> 0 | AZ24: =Saisie!AP24 -> 0 | BA24: =Saisie!AQ24 -> 0 | BB24: =Saisie!AR24 -> 0 | BC24: =Saisie!AS24 -> 0 | BD24: =Saisie!AT24 -> 0 | BE24: {=_xlfn.IFS(Saisie!AU24="OUI",1,Saisie!AU24="NON",0)} -> #N/A | BF24: =Saisie!AV24 -> 0 | BG24: =Saisie!AW24 -> 0 | BH24: {=_xlfn.IFS(Saisie!AX24="OUI",1,Saisie!AX24="NON",0)} -> #N/A | BI24: =Saisie!AY24 -> 0 | BJ24: {=_xlfn.IFS(Saisie!AZ24="OUI",1,Saisie!AZ24="NON",0)} -> #N/A | BK24: {=_xlfn.IFS(Saisie!BA24="OUI",1,Saisie!BA24="NON",0)} -> #N/A | BL24: =Saisie!BB24 -> 0 | BM24: =Saisie!BC24 -> #REF! | BN24: Même numéro de cotation que l'opération en dessous ( CF19/2023)
A25: 19 | B25: =Saisie!B25 -> 0 | C25: =Saisie!C25 -> 0 | D25: =Saisie!D25 -> 0 | E25: =Saisie!E25 -> 0 | F25: =Saisie!F25 -> 0 | G25: =Saisie!G25 -> 0 | H25: =Saisie!I25 -> 0 | I25: =Saisie!J25 -> 0 | J25: =Saisie!K25 -> 0 | K25: =Saisie!L25 -> 0 | L25: =Saisie!#REF! -> #REF! | M25: {=_xlfn.IFS(Saisie!M25="OUI",1,Saisie!M25="NON",0)} -> #N/A | N25: =Saisie!#REF! -> #REF! | O25: =Saisie!#REF! -> #REF! | P25: =Saisie!N25 -> 0 | Q25: {=_xlfn.IFS(Saisie!#REF!="OUI",1,Saisie!#REF!="NON",0)} -> #REF! | R25: =Saisie!#REF! -> #REF! | S25: =Saisie!#REF! -> #REF! | T25: =Saisie!#REF! -> #REF! | U25: =Saisie!#REF! -> #REF! | V25: {=_xlfn.IFS(Saisie!#REF!="OUI",1,Saisie!#REF!="NON",0)} -> #REF! | W25: {=_xlfn.IFS(Saisie!O25="OUI",1,Saisie!O25="NON",0)} -> #N/A | X25: =Saisie!P25 -> 0 | Y25: =Saisie!H25 -> 0 | Z25: =Saisie!#REF! -> #REF! | AA25: =Saisie!Q25 -> 0 | AB25: {=_xlfn.IFS(Saisie!R25="OUI",1,Saisie!R25="NON",0)} -> #N/A | AC25: =Saisie!S25 -> 0 | AD25: {=_xlfn.IFS(Saisie!T25="OUI",1,Saisie!T25="NON",0)} -> #N/A | AE25: =Saisie!U25 -> 0 | AF25: 3 | AG25: =Saisie!W25 -> 0 | AH25: =Saisie!X25 -> 0 | AI25: =Saisie!Y25 -> 0 | AJ25: =Saisie!Z25 -> 0 | AK25: =Saisie!AA25 -> 0 | AL25: =Saisie!AB25 -> 0 | AM25: =Saisie!AC25 -> 0 | AN25: =Saisie!AD25 -> 0 | ... AP25: =Saisie!AF25 -> 0 | AQ25: {=_xlfn.IFS(Saisie!AG25="OUI",1,Saisie!AG25="NON",0)} -> #N/A | AR25: {=_xlfn.IFS(Saisie!AH25="OUI",1,Saisie!AH25="NON",0)} -> #N/A | AS25: =Saisie!AI25 -> 0 | AT25: {=_xlfn.IFS(Saisie!AJ25="OUI",1,Saisie!AJ25="NON",0)} -> #N/A | AU25: =Saisie!AK25 -> 0 | AV25: {=_xlfn.IFS(Saisie!AL25="OUI",1,Saisie!AL25="NON",0)} -> #N/A | AW25: =Saisie!AM25 -> 0 | AX25: =Saisie!AN25 -> 0 | AY25: =Saisie!AO25 -> 0 | AZ25: =Saisie!AP25 -> 0 | BA25: =Saisie!AQ25 -> 0 | BB25: =Saisie!AR25 -> 0 | BC25: =Saisie!AS25 -> 0 | BD25: =Saisie!AT25 -> 0 | BE25: {=_xlfn.IFS(Saisie!AU25="OUI",1,Saisie!AU25="NON",0)} -> #N/A | BF25: =Saisie!AV25 -> 0 | BG25: =Saisie!AW25 -> 0 | BH25: {=_xlfn.IFS(Saisie!AX25="OUI",1,Saisie!AX25="NON",0)} -> #N/A | BI25: =Saisie!AY25 -> 0 | BJ25: {=_xlfn.IFS(Saisie!AZ25="OUI",1,Saisie!AZ25="NON",0)} -> #N/A | BK25: {=_xlfn.IFS(Saisie!BA25="OUI",1,Saisie!BA25="NON",0)} -> #N/A | BL25: =Saisie!BB25 -> 0 | BM25: =Saisie!BC25 -> #REF! | BN25: Même numéro de cotation que l'opération précedente ( CF19/2023)
A26: 20 | B26: =Saisie!B26 -> 0 | C26: =Saisie!C26 -> 0 | D26: =Saisie!D26 -> 0 | E26: =Saisie!E26 -> 0 | F26: =Saisie!F26 -> 0 | G26: =Saisie!G26 -> 0 | H26: =Saisie!I26 -> 0 | I26: =Saisie!J26 -> 0 | J26: =Saisie!K26 -> 0 | K26: =Saisie!L26 -> 0 | L26: =Saisie!#REF! -> #REF! | M26: {=_xlfn.IFS(Saisie!M26="OUI",1,Saisie!M26="NON",0)} -> #N/A | N26: =Saisie!#REF! -> #REF! | O26: =Saisie!#REF! -> #REF! | P26: =Saisie!N26 -> 0 | Q26: {=_xlfn.IFS(Saisie!#REF!="OUI",1,Saisie!#REF!="NON",0)} -> #REF! | R26: =Saisie!#REF! -> #REF! | S26: =Saisie!#REF! -> #REF! | T26: =Saisie!#REF! -> #REF! | U26: =Saisie!#REF! -> #REF! | V26: {=_xlfn.IFS(Saisie!#REF!="OUI",1,Saisie!#REF!="NON",0)} -> #REF! | W26: {=_xlfn.IFS(Saisie!O26="OUI",1,Saisie!O26="NON",0)} -> #N/A | X26: =Saisie!P26 -> 0 | Y26: =Saisie!H26 -> 0 | Z26: =Saisie!#REF! -> #REF! | AA26: =Saisie!Q26 -> 0 | AB26: {=_xlfn.IFS(Saisie!R26="OUI",1,Saisie!R26="NON",0)} -> #N/A | AC26: =Saisie!S26 -> 0 | AD26: {=_xlfn.IFS(Saisie!T26="OUI",1,Saisie!T26="NON",0)} -> #N/A | AE26: =Saisie!U26 -> 0 | AF26: 3 | AG26: =Saisie!W26 -> 0 | AH26: =Saisie!X26 -> 0 | AI26: =Saisie!Y26 -> 0 | AJ26: =Saisie!Z26 -> 0 | AK26: =Saisie!AA26 -> 0 | AL26: =Saisie!AB26 -> 0 | AM26: =Saisie!AC26 -> 0 | AN26: =Saisie!AD26 -> 0 | ... AP26: =Saisie!AF26 -> 0 | AQ26: {=_xlfn.IFS(Saisie!AG26="OUI",1,Saisie!AG26="NON",0)} -> #N/A | AR26: {=_xlfn.IFS(Saisie!AH26="OUI",1,Saisie!AH26="NON",0)} -> #N/A | AS26: =Saisie!AI26 -> 0 | AT26: {=_xlfn.IFS(Saisie!AJ26="OUI",1,Saisie!AJ26="NON",0)} -> #N/A | AU26: =Saisie!AK26 -> 0 | AV26: {=_xlfn.IFS(Saisie!AL26="OUI",1,Saisie!AL26="NON",0)} -> #N/A | AW26: =Saisie!AM26 -> 0 | AX26: =Saisie!AN26 -> 0 | AY26: =Saisie!AO26 -> 0 | AZ26: =Saisie!AP26 -> 0 | BA26: =Saisie!AQ26 -> 0 | BB26: =Saisie!AR26 -> 0 | BC26: =Saisie!AS26 -> 0 | BD26: =Saisie!AT26 -> 0 | BE26: {=_xlfn.IFS(Saisie!AU26="OUI",1,Saisie!AU26="NON",0)} -> #N/A | BF26: =Saisie!AV26 -> 0 | BG26: =Saisie!AW26 -> 0 | BH26: {=_xlfn.IFS(Saisie!AX26="OUI",1,Saisie!AX26="NON",0)} -> #N/A | BI26: =Saisie!AY26 -> 0 | BJ26: {=_xlfn.IFS(Saisie!AZ26="OUI",1,Saisie!AZ26="NON",0)} -> #N/A | BK26: {=_xlfn.IFS(Saisie!BA26="OUI",1,Saisie!BA26="NON",0)} -> #N/A | BL26: =Saisie!BB26 -> 0 | BM26: =Saisie!BC26 -> #REF!
A27: 21 | B27: =Saisie!B27 -> 0 | C27: =Saisie!C27 -> 0 | D27: =Saisie!D27 -> 0 | E27: =Saisie!E27 -> 0 | F27: =Saisie!F27 -> 0 | G27: =Saisie!G27 -> 0 | H27: =Saisie!I27 -> 0 | I27: =Saisie!J27 -> 0 | J27: =Saisie!K27 -> 0 | K27: =Saisie!L27 -> 0 | L27: =Saisie!#REF! -> #REF! | M27: {=_xlfn.IFS(Saisie!M27="OUI",1,Saisie!M27="NON",0)} -> #N/A | N27: =Saisie!#REF! -> #REF! | O27: =Saisie!#REF! -> #REF! | P27: =Saisie!N27 -> 0 | Q27: {=_xlfn.IFS(Saisie!#REF!="OUI",1,Saisie!#REF!="NON",0)} -> #REF! | R27: =Saisie!#REF! -> #REF! | S27: =Saisie!#REF! -> #REF! | T27: =Saisie!#REF! -> #REF! | U27: =Saisie!#REF! -> #REF! | V27: {=_xlfn.IFS(Saisie!#REF!="OUI",1,Saisie!#REF!="NON",0)} -> #REF! | W27: {=_xlfn.IFS(Saisie!O27="OUI",1,Saisie!O27="NON",0)} -> #N/A | X27: =Saisie!P27 -> 0 | Y27: =Saisie!H27 -> 0 | Z27: =Saisie!#REF! -> #REF! | AA27: =Saisie!Q27 -> 0 | AB27: {=_xlfn.IFS(Saisie!R27="OUI",1,Saisie!R27="NON",0)} -> #N/A | AC27: =Saisie!S27 -> 0 | AD27: {=_xlfn.IFS(Saisie!T27="OUI",1,Saisie!T27="NON",0)} -> #N/A | AE27: =Saisie!U27 -> 0 | AF27: 3 | AG27: =Saisie!W27 -> 0 | AH27: =Saisie!X27 -> 0 | AI27: =Saisie!Y27 -> 0 | AJ27: =Saisie!Z27 -> 0 | AK27: =Saisie!AA27 -> 0 | AL27: =Saisie!AB27 -> 0 | AM27: =Saisie!AC27 -> 0 | AN27: =Saisie!AD27 -> 0 | ... AP27: =Saisie!AF27 -> 0 | AQ27: {=_xlfn.IFS(Saisie!AG27="OUI",1,Saisie!AG27="NON",0)} -> #N/A | AR27: {=_xlfn.IFS(Saisie!AH27="OUI",1,Saisie!AH27="NON",0)} -> #N/A | AS27: =Saisie!AI27 -> 0 | AT27: {=_xlfn.IFS(Saisie!AJ27="OUI",1,Saisie!AJ27="NON",0)} -> #N/A | AU27: =Saisie!AK27 -> 0 | AV27: {=_xlfn.IFS(Saisie!AL27="OUI",1,Saisie!AL27="NON",0)} -> #N/A | AW27: =Saisie!AM27 -> 0 | AX27: =Saisie!AN27 -> 0 | AY27: =Saisie!AO27 -> 0 | AZ27: =Saisie!AP27 -> 0 | BA27: =Saisie!AQ27 -> 0 | BB27: =Saisie!AR27 -> 0 | BC27: =Saisie!AS27 -> 0 | BD27: =Saisie!AT27 -> 0 | BE27: {=_xlfn.IFS(Saisie!AU27="OUI",1,Saisie!AU27="NON",0)} -> #N/A | BF27: =Saisie!AV27 -> 0 | BG27: =Saisie!AW27 -> 0 | BH27: {=_xlfn.IFS(Saisie!AX27="OUI",1,Saisie!AX27="NON",0)} -> #N/A | BI27: =Saisie!AY27 -> 0 | BJ27: {=_xlfn.IFS(Saisie!AZ27="OUI",1,Saisie!AZ27="NON",0)} -> #N/A | BK27: {=_xlfn.IFS(Saisie!BA27="OUI",1,Saisie!BA27="NON",0)} -> #N/A | BL27: =Saisie!BB27 -> 0 | BM27: =Saisie!BC27 -> #REF!
A28: 22 | B28: =Saisie!B28 -> 0 | C28: =Saisie!C28 -> 0 | D28: =Saisie!D28 -> 0 | E28: =Saisie!E28 -> 0 | F28: =Saisie!F28 -> 0 | G28: =Saisie!G28 -> 0 | H28: =Saisie!I28 -> 0 | I28: =Saisie!J28 -> 0 | J28: =Saisie!K28 -> 0 | K28: =Saisie!L28 -> 0 | L28: =Saisie!#REF! -> #REF! | M28: {=_xlfn.IFS(Saisie!M28="OUI",1,Saisie!M28="NON",0)} -> #N/A | N28: =Saisie!#REF! -> #REF! | O28: =Saisie!#REF! -> #REF! | P28: =Saisie!N28 -> 0 | Q28: {=_xlfn.IFS(Saisie!#REF!="OUI",1,Saisie!#REF!="NON",0)} -> #REF! | R28: =Saisie!#REF! -> #REF! | S28: =Saisie!#REF! -> #REF! | T28: =Saisie!#REF! -> #REF! | U28: =Saisie!#REF! -> #REF! | V28: {=_xlfn.IFS(Saisie!#REF!="OUI",1,Saisie!#REF!="NON",0)} -> #REF! | W28: {=_xlfn.IFS(Saisie!O28="OUI",1,Saisie!O28="NON",0)} -> #N/A | X28: =Saisie!P28 -> 0 | Y28: =Saisie!H28 -> 0 | Z28: =Saisie!#REF! -> #REF! | AA28: =Saisie!Q28 -> 0 | AB28: {=_xlfn.IFS(Saisie!R28="OUI",1,Saisie!R28="NON",0)} -> #N/A | AC28: =Saisie!S28 -> 0 | AD28: {=_xlfn.IFS(Saisie!T28="OUI",1,Saisie!T28="NON",0)} -> #N/A | AE28: =Saisie!U28 -> 0 | AF28: 3 | AG28: =Saisie!W28 -> 0 | AH28: =Saisie!X28 -> 0 | AI28: =Saisie!Y28 -> 0 | AJ28: =Saisie!Z28 -> 0 | AK28: =Saisie!AA28 -> 0 | AL28: =Saisie!AB28 -> 0 | AM28: =Saisie!AC28 -> 0 | AN28: =Saisie!AD28 -> 0 | ... AP28: =Saisie!AF28 -> 0 | AQ28: {=_xlfn.IFS(Saisie!AG28="OUI",1,Saisie!AG28="NON",0)} -> #N/A | AR28: {=_xlfn.IFS(Saisie!AH28="OUI",1,Saisie!AH28="NON",0)} -> #N/A | AS28: =Saisie!AI28 -> 0 | AT28: {=_xlfn.IFS(Saisie!AJ28="OUI",1,Saisie!AJ28="NON",0)} -> #N/A | AU28: =Saisie!AK28 -> 0 | AV28: {=_xlfn.IFS(Saisie!AL28="OUI",1,Saisie!AL28="NON",0)} -> #N/A | AW28: =Saisie!AM28 -> 0 | AX28: =Saisie!AN28 -> 0 | AY28: =Saisie!AO28 -> 0 | AZ28: =Saisie!AP28 -> 0 | BA28: =Saisie!AQ28 -> 0 | BB28: =Saisie!AR28 -> 0 | BC28: =Saisie!AS28 -> 0 | BD28: =Saisie!AT28 -> 0 | BE28: {=_xlfn.IFS(Saisie!AU28="OUI",1,Saisie!AU28="NON",0)} -> #N/A | BF28: =Saisie!AV28 -> 0 | BG28: =Saisie!AW28 -> 0 | BH28: {=_xlfn.IFS(Saisie!AX28="OUI",1,Saisie!AX28="NON",0)} -> #N/A | BI28: =Saisie!AY28 -> 0 | BJ28: {=_xlfn.IFS(Saisie!AZ28="OUI",1,Saisie!AZ28="NON",0)} -> #N/A | BK28: {=_xlfn.IFS(Saisie!BA28="OUI",1,Saisie!BA28="NON",0)} -> #N/A | BL28: =Saisie!BB28 -> 0 | BM28: =Saisie!BC28 -> #REF!
A29: 23 | B29: =Saisie!B29 -> 0 | C29: =Saisie!C29 -> 0 | D29: =Saisie!D29 -> 0 | E29: =Saisie!E29 -> 0 | F29: =Saisie!F29 -> 0 | G29: =Saisie!G29 -> 0 | H29: =Saisie!I29 -> 0 | I29: =Saisie!J29 -> 0 | J29: =Saisie!K29 -> 0 | K29: =Saisie!L29 -> 0 | L29: =Saisie!#REF! -> #REF! | M29: {=_xlfn.IFS(Saisie!M29="OUI",1,Saisie!M29="NON",0)} -> #N/A | N29: =Saisie!#REF! -> #REF! | O29: =Saisie!#REF! -> #REF! | P29: =Saisie!N29 -> 0 | Q29: {=_xlfn.IFS(Saisie!#REF!="OUI",1,Saisie!#REF!="NON",0)} -> #REF! | R29: =Saisie!#REF! -> #REF! | S29: =Saisie!#REF! -> #REF! | T29: =Saisie!#REF! -> #REF! | U29: =Saisie!#REF! -> #REF! | V29: {=_xlfn.IFS(Saisie!#REF!="OUI",1,Saisie!#REF!="NON",0)} -> #REF! | W29: {=_xlfn.IFS(Saisie!O29="OUI",1,Saisie!O29="NON",0)} -> #N/A | X29: =Saisie!P29 -> 0 | Y29: =Saisie!H29 -> 0 | Z29: =Saisie!#REF! -> #REF! | AA29: =Saisie!Q29 -> 0 | AB29: {=_xlfn.IFS(Saisie!R29="OUI",1,Saisie!R29="NON",0)} -> #N/A | AC29: =Saisie!S29 -> 0 | AD29: {=_xlfn.IFS(Saisie!T29="OUI",1,Saisie!T29="NON",0)} -> #N/A | AE29: =Saisie!U29 -> 0 | AF29: 3 | AG29: =Saisie!W29 -> 0 | AH29: =Saisie!X29 -> 0 | AI29: =Saisie!Y29 -> 0 | AJ29: =Saisie!Z29 -> 0 | AK29: =Saisie!AA29 -> 0 | AL29: =Saisie!AB29 -> 0 | AM29: =Saisie!AC29 -> 0 | AN29: =Saisie!AD29 -> 0 | ... AP29: =Saisie!AF29 -> 0 | AQ29: {=_xlfn.IFS(Saisie!AG29="OUI",1,Saisie!AG29="NON",0)} -> #N/A | AR29: {=_xlfn.IFS(Saisie!AH29="OUI",1,Saisie!AH29="NON",0)} -> #N/A | AS29: =Saisie!AI29 -> 0 | AT29: {=_xlfn.IFS(Saisie!AJ29="OUI",1,Saisie!AJ29="NON",0)} -> #N/A | AU29: =Saisie!AK29 -> 0 | AV29: {=_xlfn.IFS(Saisie!AL29="OUI",1,Saisie!AL29="NON",0)} -> #N/A | AW29: =Saisie!AM29 -> 0 | AX29: =Saisie!AN29 -> 0 | AY29: =Saisie!AO29 -> 0 | AZ29: =Saisie!AP29 -> 0 | BA29: =Saisie!AQ29 -> 0 | BB29: =Saisie!AR29 -> 0 | BC29: =Saisie!AS29 -> 0 | BD29: =Saisie!AT29 -> 0 | BE29: {=_xlfn.IFS(Saisie!AU29="OUI",1,Saisie!AU29="NON",0)} -> #N/A | BF29: =Saisie!AV29 -> 0 | BG29: =Saisie!AW29 -> 0 | BH29: {=_xlfn.IFS(Saisie!AX29="OUI",1,Saisie!AX29="NON",0)} -> #N/A | BI29: =Saisie!AY29 -> 0 | BJ29: {=_xlfn.IFS(Saisie!AZ29="OUI",1,Saisie!AZ29="NON",0)} -> #N/A | BK29: {=_xlfn.IFS(Saisie!BA29="OUI",1,Saisie!BA29="NON",0)} -> #N/A | BL29: =Saisie!BB29 -> 0 | BM29: =Saisie!BC29 -> #REF!
A30: 24 | B30: =Saisie!B30 -> 0 | C30: =Saisie!C30 -> 0 | D30: =Saisie!D30 -> 0 | E30: =Saisie!E30 -> 0 | F30: =Saisie!F30 -> 0 | G30: =Saisie!G30 -> 0 | H30: =Saisie!I30 -> 0 | I30: =Saisie!J30 -> 0 | J30: =Saisie!K30 -> 0 | K30: =Saisie!L30 -> 0 | L30: =Saisie!#REF! -> #REF! | M30: {=_xlfn.IFS(Saisie!M30="OUI",1,Saisie!M30="NON",0)} -> #N/A | N30: =Saisie!#REF! -> #REF! | O30: =Saisie!#REF! -> #REF! | P30: =Saisie!N30 -> 0 | Q30: {=_xlfn.IFS(Saisie!#REF!="OUI",1,Saisie!#REF!="NON",0)} -> #REF! | R30: =Saisie!#REF! -> #REF! | S30: =Saisie!#REF! -> #REF! | T30: =Saisie!#REF! -> #REF! | U30: =Saisie!#REF! -> #REF! | V30: {=_xlfn.IFS(Saisie!#REF!="OUI",1,Saisie!#REF!="NON",0)} -> #REF! | W30: {=_xlfn.IFS(Saisie!O30="OUI",1,Saisie!O30="NON",0)} -> #N/A | X30: =Saisie!P30 -> 0 | Y30: =Saisie!H30 -> 0 | Z30: =Saisie!#REF! -> #REF! | AA30: =Saisie!Q30 -> 0 | AB30: {=_xlfn.IFS(Saisie!R30="OUI",1,Saisie!R30="NON",0)} -> #N/A | AC30: =Saisie!S30 -> 0 | AD30: {=_xlfn.IFS(Saisie!T30="OUI",1,Saisie!T30="NON",0)} -> #N/A | AE30: =Saisie!U30 -> 0 | AF30: 3 | AG30: =Saisie!W30 -> 0 | AH30: =Saisie!X30 -> 0 | AI30: =Saisie!Y30 -> 0 | AJ30: =Saisie!Z30 -> 0 | AK30: =Saisie!AA30 -> 0 | AL30: =Saisie!AB30 -> 0 | AM30: =Saisie!AC30 -> 0 | AN30: =Saisie!AD30 -> 0 | ... AP30: =Saisie!AF30 -> 0 | AQ30: {=_xlfn.IFS(Saisie!AG30="OUI",1,Saisie!AG30="NON",0)} -> #N/A | AR30: {=_xlfn.IFS(Saisie!AH30="OUI",1,Saisie!AH30="NON",0)} -> #N/A | AS30: =Saisie!AI30 -> 0 | AT30: {=_xlfn.IFS(Saisie!AJ30="OUI",1,Saisie!AJ30="NON",0)} -> #N/A | AU30: =Saisie!AK30 -> 0 | AV30: {=_xlfn.IFS(Saisie!AL30="OUI",1,Saisie!AL30="NON",0)} -> #N/A | AW30: =Saisie!AM30 -> 0 | AX30: =Saisie!AN30 -> 0 | AY30: =Saisie!AO30 -> 0 | AZ30: =Saisie!AP30 -> 0 | BA30: =Saisie!AQ30 -> 0 | BB30: =Saisie!AR30 -> 0 | BC30: =Saisie!AS30 -> 0 | BD30: =Saisie!AT30 -> 0 | BE30: {=_xlfn.IFS(Saisie!AU30="OUI",1,Saisie!AU30="NON",0)} -> #N/A | BF30: =Saisie!AV30 -> 0 | BG30: =Saisie!AW30 -> 0 | BH30: {=_xlfn.IFS(Saisie!AX30="OUI",1,Saisie!AX30="NON",0)} -> #N/A | BI30: =Saisie!AY30 -> 0 | BJ30: {=_xlfn.IFS(Saisie!AZ30="OUI",1,Saisie!AZ30="NON",0)} -> #N/A | BK30: {=_xlfn.IFS(Saisie!BA30="OUI",1,Saisie!BA30="NON",0)} -> #N/A | BL30: =Saisie!BB30 -> 0 | BM30: =Saisie!BC30 -> #REF!
A31: 25 | B31: =Saisie!B31 -> 0 | C31: =Saisie!C31 -> 0 | D31: =Saisie!D31 -> 0 | E31: =Saisie!E31 -> 0 | F31: =Saisie!F31 -> 0 | G31: =Saisie!G31 -> 0 | H31: =Saisie!I31 -> 0 | I31: =Saisie!J31 -> 0 | J31: =Saisie!K31 -> 0 | K31: =Saisie!L31 -> 0 | L31: =Saisie!#REF! -> #REF! | M31: {=_xlfn.IFS(Saisie!M31="OUI",1,Saisie!M31="NON",0)} -> #N/A | N31: =Saisie!#REF! -> #REF! | O31: =Saisie!#REF! -> #REF! | P31: =Saisie!N31 -> 0 | Q31: {=_xlfn.IFS(Saisie!#REF!="OUI",1,Saisie!#REF!="NON",0)} -> #REF! | R31: =Saisie!#REF! -> #REF! | S31: =Saisie!#REF! -> #REF! | T31: =Saisie!#REF! -> #REF! | U31: =Saisie!#REF! -> #REF! | V31: {=_xlfn.IFS(Saisie!#REF!="OUI",1,Saisie!#REF!="NON",0)} -> #REF! | W31: {=_xlfn.IFS(Saisie!O31="OUI",1,Saisie!O31="NON",0)} -> #N/A | X31: =Saisie!P31 -> 0 | Y31: =Saisie!H31 -> 0 | Z31: =Saisie!#REF! -> #REF! | AA31: =Saisie!Q31 -> 0 | AB31: {=_xlfn.IFS(Saisie!R31="OUI",1,Saisie!R31="NON",0)} -> #N/A | AC31: =Saisie!S31 -> 0 | AD31: {=_xlfn.IFS(Saisie!T31="OUI",1,Saisie!T31="NON",0)} -> #N/A | AE31: =Saisie!U31 -> 0 | AF31: 3 | AG31: =Saisie!W31 -> 0 | AH31: =Saisie!X31 -> 0 | AI31: =Saisie!Y31 -> 0 | AJ31: =Saisie!Z31 -> 0 | AK31: =Saisie!AA31 -> 0 | AL31: =Saisie!AB31 -> 0 | AM31: =Saisie!AC31 -> 0 | AN31: =Saisie!AD31 -> 0 | ... AP31: =Saisie!AF31 -> 0 | AQ31: {=_xlfn.IFS(Saisie!AG31="OUI",1,Saisie!AG31="NON",0)} -> #N/A | AR31: {=_xlfn.IFS(Saisie!AH31="OUI",1,Saisie!AH31="NON",0)} -> #N/A | AS31: =Saisie!AI31 -> 0 | AT31: {=_xlfn.IFS(Saisie!AJ31="OUI",1,Saisie!AJ31="NON",0)} -> #N/A | AU31: =Saisie!AK31 -> 0 | AV31: {=_xlfn.IFS(Saisie!AL31="OUI",1,Saisie!AL31="NON",0)} -> #N/A | AW31: =Saisie!AM31 -> 0 | AX31: =Saisie!AN31 -> 0 | AY31: =Saisie!AO31 -> 0 | AZ31: =Saisie!AP31 -> 0 | BA31: =Saisie!AQ31 -> 0 | BB31: =Saisie!AR31 -> 0 | BC31: =Saisie!AS31 -> 0 | BD31: =Saisie!AT31 -> 0 | BE31: {=_xlfn.IFS(Saisie!AU31="OUI",1,Saisie!AU31="NON",0)} -> #N/A | BF31: =Saisie!AV31 -> 0 | BG31: =Saisie!AW31 -> 0 | BH31: {=_xlfn.IFS(Saisie!AX31="OUI",1,Saisie!AX31="NON",0)} -> #N/A | BI31: =Saisie!AY31 -> 0 | BJ31: {=_xlfn.IFS(Saisie!AZ31="OUI",1,Saisie!AZ31="NON",0)} -> #N/A | BK31: {=_xlfn.IFS(Saisie!BA31="OUI",1,Saisie!BA31="NON",0)} -> #N/A | BL31: =Saisie!BB31 -> 0 | BM31: =Saisie!BC31 -> #REF!
A32: 26 | B32: =Saisie!B32 -> 0 | C32: =Saisie!C32 -> 0 | D32: =Saisie!D32 -> 0 | E32: =Saisie!E32 -> 0 | F32: =Saisie!F32 -> 0 | G32: =Saisie!G32 -> 0 | H32: =Saisie!I32 -> 0 | I32: =Saisie!J32 -> 0 | J32: =Saisie!K32 -> 0 | K32: =Saisie!L32 -> 0 | L32: =Saisie!#REF! -> #REF! | M32: {=_xlfn.IFS(Saisie!M32="OUI",1,Saisie!M32="NON",0)} -> #N/A | N32: =Saisie!#REF! -> #REF! | O32: =Saisie!#REF! -> #REF! | P32: =Saisie!N32 -> 0 | Q32: {=_xlfn.IFS(Saisie!#REF!="OUI",1,Saisie!#REF!="NON",0)} -> #REF! | R32: =Saisie!#REF! -> #REF! | S32: =Saisie!#REF! -> #REF! | T32: =Saisie!#REF! -> #REF! | U32: =Saisie!#REF! -> #REF! | V32: {=_xlfn.IFS(Saisie!#REF!="OUI",1,Saisie!#REF!="NON",0)} -> #REF! | W32: {=_xlfn.IFS(Saisie!O32="OUI",1,Saisie!O32="NON",0)} -> #N/A | X32: =Saisie!P32 -> 0 | Y32: =Saisie!H32 -> 0 | Z32: =Saisie!#REF! -> #REF! | AA32: =Saisie!Q32 -> 0 | AB32: {=_xlfn.IFS(Saisie!R32="OUI",1,Saisie!R32="NON",0)} -> #N/A | AC32: =Saisie!S32 -> 0 | AD32: {=_xlfn.IFS(Saisie!T32="OUI",1,Saisie!T32="NON",0)} -> #N/A | AE32: =Saisie!U32 -> 0 | AF32: 3 | AG32: =Saisie!W32 -> 0 | AH32: =Saisie!X32 -> 0 | AI32: =Saisie!Y32 -> 0 | AJ32: =Saisie!Z32 -> 0 | AK32: =Saisie!AA32 -> 0 | AL32: =Saisie!AB32 -> 0 | AM32: =Saisie!AC32 -> 0 | AN32: =Saisie!AD32 -> 0 | ... AP32: =Saisie!AF32 -> 0 | AQ32: {=_xlfn.IFS(Saisie!AG32="OUI",1,Saisie!AG32="NON",0)} -> #N/A | AR32: {=_xlfn.IFS(Saisie!AH32="OUI",1,Saisie!AH32="NON",0)} -> #N/A | AS32: =Saisie!AI32 -> 0 | AT32: {=_xlfn.IFS(Saisie!AJ32="OUI",1,Saisie!AJ32="NON",0)} -> #N/A | AU32: =Saisie!AK32 -> 0 | AV32: {=_xlfn.IFS(Saisie!AL32="OUI",1,Saisie!AL32="NON",0)} -> #N/A | AW32: =Saisie!AM32 -> 0 | AX32: =Saisie!AN32 -> 0 | AY32: =Saisie!AO32 -> 0 | AZ32: =Saisie!AP32 -> 0 | BA32: =Saisie!AQ32 -> 0 | BB32: =Saisie!AR32 -> 0 | BC32: =Saisie!AS32 -> 0 | BD32: =Saisie!AT32 -> 0 | BE32: {=_xlfn.IFS(Saisie!AU32="OUI",1,Saisie!AU32="NON",0)} -> #N/A | BF32: =Saisie!AV32 -> 0 | BG32: =Saisie!AW32 -> 0 | BH32: {=_xlfn.IFS(Saisie!AX32="OUI",1,Saisie!AX32="NON",0)} -> #N/A | BI32: =Saisie!AY32 -> 0 | BJ32: {=_xlfn.IFS(Saisie!AZ32="OUI",1,Saisie!AZ32="NON",0)} -> #N/A | BK32: {=_xlfn.IFS(Saisie!BA32="OUI",1,Saisie!BA32="NON",0)} -> #N/A | BL32: =Saisie!BB32 -> 0 | BM32: =Saisie!BC32 -> #REF!
A33: 27 | B33: =Saisie!B33 -> 0 | C33: =Saisie!C33 -> 0 | D33: =Saisie!D33 -> 0 | E33: =Saisie!E33 -> 0 | F33: =Saisie!F33 -> 0 | G33: =Saisie!G33 -> 0 | H33: =Saisie!I33 -> 0 | I33: =Saisie!J33 -> 0 | J33: =Saisie!K33 -> 0 | K33: =Saisie!L33 -> 0 | L33: =Saisie!#REF! -> #REF! | M33: {=_xlfn.IFS(Saisie!M33="OUI",1,Saisie!M33="NON",0)} -> #N/A | N33: =Saisie!#REF! -> #REF! | O33: =Saisie!#REF! -> #REF! | P33: =Saisie!N33 -> 0 | Q33: {=_xlfn.IFS(Saisie!#REF!="OUI",1,Saisie!#REF!="NON",0)} -> #REF! | R33: =Saisie!#REF! -> #REF! | S33: =Saisie!#REF! -> #REF! | T33: =Saisie!#REF! -> #REF! | U33: =Saisie!#REF! -> #REF! | V33: {=_xlfn.IFS(Saisie!#REF!="OUI",1,Saisie!#REF!="NON",0)} -> #REF! | W33: {=_xlfn.IFS(Saisie!O33="OUI",1,Saisie!O33="NON",0)} -> #N/A | X33: =Saisie!P33 -> 0 | Y33: =Saisie!H33 -> 0 | Z33: =Saisie!#REF! -> #REF! | AA33: =Saisie!Q33 -> 0 | AB33: {=_xlfn.IFS(Saisie!R33="OUI",1,Saisie!R33="NON",0)} -> #N/A | AC33: =Saisie!S33 -> 0 | AD33: {=_xlfn.IFS(Saisie!T33="OUI",1,Saisie!T33="NON",0)} -> #N/A | AE33: =Saisie!U33 -> 0 | AF33: 3 | AG33: =Saisie!W33 -> 0 | AH33: =Saisie!X33 -> 0 | AI33: =Saisie!Y33 -> 0 | AJ33: =Saisie!Z33 -> 0 | AK33: =Saisie!AA33 -> 0 | AL33: =Saisie!AB33 -> 0 | AM33: =Saisie!AC33 -> 0 | AN33: =Saisie!AD33 -> 0 | ... AP33: =Saisie!AF33 -> 0 | AQ33: {=_xlfn.IFS(Saisie!AG33="OUI",1,Saisie!AG33="NON",0)} -> #N/A | AR33: {=_xlfn.IFS(Saisie!AH33="OUI",1,Saisie!AH33="NON",0)} -> #N/A | AS33: =Saisie!AI33 -> 0 | AT33: {=_xlfn.IFS(Saisie!AJ33="OUI",1,Saisie!AJ33="NON",0)} -> #N/A | AU33: =Saisie!AK33 -> 0 | AV33: {=_xlfn.IFS(Saisie!AL33="OUI",1,Saisie!AL33="NON",0)} -> #N/A | AW33: =Saisie!AM33 -> 0 | AX33: =Saisie!AN33 -> 0 | AY33: =Saisie!AO33 -> 0 | AZ33: =Saisie!AP33 -> 0 | BA33: =Saisie!AQ33 -> 0 | BB33: =Saisie!AR33 -> 0 | BC33: =Saisie!AS33 -> 0 | BD33: =Saisie!AT33 -> 0 | BE33: {=_xlfn.IFS(Saisie!AU33="OUI",1,Saisie!AU33="NON",0)} -> #N/A | BF33: =Saisie!AV33 -> 0 | BG33: =Saisie!AW33 -> 0 | BH33: {=_xlfn.IFS(Saisie!AX33="OUI",1,Saisie!AX33="NON",0)} -> #N/A | BI33: =Saisie!AY33 -> 0 | BJ33: {=_xlfn.IFS(Saisie!AZ33="OUI",1,Saisie!AZ33="NON",0)} -> #N/A | BK33: {=_xlfn.IFS(Saisie!BA33="OUI",1,Saisie!BA33="NON",0)} -> #N/A | BL33: =Saisie!BB33 -> 0 | BM33: =Saisie!BC33 -> #REF!
