Workbook

Sheet Saisie
B2: I1 | C2: I2 | D2: I3 | E2: I4 | F2: I5 | G2: I6 | H2: Q4 | J2: I8 | K2: I9 | M2: I10 | N2: Q1 | R2: Q6 | U2: Q7 | AA2: Q13 | AB2: Q14 | AC2: Q17
B3: GUIDE DES OPERATIONS EN PSD (Décret n°2021-909 du 22 décembre 2021 fixant les modalités d'exécution des crédits budgétaires dans le cadre des procédures prévues par le Code des marchés publics) | N3: Article 20.1 CMP | R3: Article 6 | S3: Article 19.4 CMP | AC3: Arrêté interministériel N° 484 MEF/DGBF/DMP du 09 novembre 2011
B4: Montant inférieur à 10 000 000 FCFA
A5: N° | B5: Contrôleur | C5: Date de contrôle | D5: Ministère | E5: Autorité Contractante | F5: Personne Ressource | G5: Imputation Budgétaire | H5: Montant de la dotation/ou du crédit : | I5: Numéro de l'opération | J5: Objet de l'opération | K5: Nature de l'opération | N5: Préparation du PSPM | R5: Montant de l'estimation | S5: Opération réservée aux PME | U5: Date de commande | W5: Attributaire (s) | AA5: Ecart entre montant crédit autorisé et montant attribué | AB5: Situation d'exécution de la ligne budgetaire après passation | AC5: Existence et exhaustivité de l’archivage des documents | AF5: Temps total pour la conduite de l’opération
B6: Nom de l'Agent DGMP | F6: Interlocuteur chez l'AC | H6: Montant | K6: Travaux/ Fournitures/ Prestations | L6: NB | M6: Observations | N6: Existence du PSPM | O6: Observations | P6: Respect du PSPM | Q6: Observations | R6: Montant | S6: Constat | T6: Observations | U6: Date | V6: Observations | W6: Raison sociale | X6: NCC attributaire | Y6: Montant | Z6: Observations | AA6: Montant | AB6: Montant disponible | AC6: Existence | AD6: Exhaustivité | AE6: Observations | AF6: Nombre de jour de l'opération | AG6: Observations
AA9: =#REF!-Y9 -> #REF! | AF9: =IF(OR(#REF!="",#REF!="")=TRUE,"",NETWORKDAYS.INTL(#REF!,#REF!)) -> #REF!
AA10: =#REF!-Y10 -> #REF! | AF10: =IF(OR(#REF!="",#REF!="")=TRUE,"",NETWORKDAYS.INTL(#REF!,#REF!)) -> #REF!
AA11: =#REF!-Y11 -> #REF! | AF11: =IF(OR(#REF!="",#REF!="")=TRUE,"",NETWORKDAYS.INTL(#REF!,#REF!)) -> #REF!
AA12: =#REF!-Y12 -> #REF! | AF12: =IF(OR(#REF!="",#REF!="")=TRUE,"",NETWORKDAYS.INTL(#REF!,#REF!)) -> #REF!
AA13: =#REF!-Y13 -> #REF! | AF13: =IF(OR(#REF!="",#REF!="")=TRUE,"",NETWORKDAYS.INTL(#REF!,#REF!)) -> #REF!
AA14: =#REF!-Y14 -> #REF! | AF14: =IF(OR(#REF!="",#REF!="")=TRUE,"",NETWORKDAYS.INTL(#REF!,#REF!)) -> #REF!
AA15: =#REF!-Y15 -> #REF! | AF15: =IF(OR(#REF!="",#REF!="")=TRUE,"",NETWORKDAYS.INTL(#REF!,#REF!)) -> #REF!
AA16: =#REF!-Y16 -> #REF! | AF16: =IF(OR(#REF!="",#REF!="")=TRUE,"",NETWORKDAYS.INTL(#REF!,#REF!)) -> #REF!
AA17: =#REF!-Y17 -> #REF! | AF17: =IF(OR(#REF!="",#REF!="")=TRUE,"",NETWORKDAYS.INTL(#REF!,#REF!)) -> #REF!
AA18: =#REF!-Y18 -> #REF! | AF18: =IF(OR(#REF!="",#REF!="")=TRUE,"",NETWORKDAYS.INTL(#REF!,#REF!)) -> #REF!
AA19: =#REF!-Y19 -> #REF! | AF19: =IF(OR(#REF!="",#REF!="")=TRUE,"",NETWORKDAYS.INTL(#REF!,#REF!)) -> #REF!
AA20: =#REF!-Y20 -> #REF! | AF20: =IF(OR(#REF!="",#REF!="")=TRUE,"",NETWORKDAYS.INTL(#REF!,#REF!)) -> #REF!
... AA29: =#REF!-Y29 -> #REF! | AF29: =IF(OR(#REF!="",#REF!="")=TRUE,"",NETWORKDAYS.INTL(#REF!,#REF!)) -> #REF!
AA30: =#REF!-Y30 -> #REF! | AF30: #REF!
AA31: =#REF!-Y31 -> #REF! | AF31: #REF!
AA32: =#REF!-Y32 -> #REF! | AF32: #REF!
AA33: =#REF!-Y33 -> #REF! | AF33: #REF!
AA34: =#REF!-Y34 -> #REF! | AF34: #REF!
AA35: =#REF!-Y35 -> #REF! | AF35: #REF!
AA36: =#REF!-Y36 -> #REF! | AF36: #REF!
AA37: =#REF!-Y37 -> #REF! | AF37: #REF!
AA38: =#REF!-Y38 -> #REF! | AF38: #REF!
AA39: =#REF!-Y39 -> #REF! | AF39: #REF!
AA40: =#REF!-Y40 -> #REF! | AF40: #REF!
AA41: =#REF!-Y41 -> #REF! | AF41: #REF!
... AA65: =#REF!-Y65 -> #REF! | AF65: #REF!
AA66: =#REF!-Y66 -> #REF!
AA67: =#REF!-Y67 -> #REF!
AA68: =#REF!-Y68 -> #REF!
AA69: =#REF!-Y69 -> #REF!
AA70: =#REF!-Y70 -> #REF!
AA71: =#REF!-Y71 -> #REF!
AA72: =#REF!-Y72 -> #REF!
AA73: =#REF!-Y73 -> #REF!
AA74: =#REF!-Y74 -> #REF!
...

Sheet Formule
B2: I1 | C2: I2 | D2: I3 | E2: I4 | F2: I5 | G2: I6 | I2: I8 | J2: I9 | L2: I10 | M2: Q4 | N2: Q5 | O2: Q1 | X2: Q3 | AA2: Q6 | AD2: Q7 | AJ2: Q13 | AK2: Q14 | AL2: Q17
B3: GUIDE DES OPERATIONS EN PSD (Décret n°2021-909 du 22 décembre 2021 fixant les modalités d'exécution des crédits budgétaires dans le cadre des procédures prévues par le Code des marchés publics) | M3: Article 6 | O3: Article 20.1 CMP | X3: Article 20.3 CMP | AA3: Article 6 | AB3: Article 19.4 CMP | AL3: Arrêté interministériel N° 484 MEF/DGBF/DMP du 09 novembre 2011
B4: Montant inférieur à 10 000 000 FCFA
A5: N° | B5: Contrôleur | C5: Date de contrôle | D5: Ministère | E5: Autorité Contractante | F5: Personne Ressource | G5: Imputation Budgétaire | H5: Numéro de l'opération | I5: Objet de l'opération | J5: Nature de l'opération | M5: Montant de la dotation/ou du crédit : | N5: Situation d'exécution de la ligne budgetaire avant passation | O5: Préparation du PSPM | S5: Publication du PSPM | X5: Inscription de l’opération au PSPM et respect du PSPM | AA5: Montant de l'estimation | AB5: Opération réservée aux PME | AD5: Date de commande | AF5: Attributaire (s) | AJ5: Ecart entre montant crédit autorisé et montant attribué | AK5: Situation d'exécution de la ligne budgetaire après passation | AL5: Existence et exhaustivité de l’archivage des documents | AO5: Temps total pour la conduite de l’opération
B6: Nom de l'Agent DGMP | F6: Interlocuteur chez l'AC | J6: Travaux/ Fournitures/ Prestations | K6: NB | L6: Observations | M6: Montant | N6: Montant disponible | O6: Existence du PSPM | P6: Date de notification du budget à l'AC | Q6: Date de soumission du PSPM à la DGMP pour validation | R6: Observations | S6: Constat | T6: Date | U6: Support | V6: Numéro du BOMP | W6: Observations | X6: Opération inscrite au PSPM | Y6: Respect du PSPM | Z6: Observations | AA6: Montant | AB6: Constat | AC6: Observations | AD6: Date | AE6: Observations | AF6: Raison sociale | AG6: NCC attributaire | AH6: Montant | AI6: Observations | AJ6: Montant | AK6: Montant disponible | AL6: Existence | AM6: Exhaustivité | AN6: Observations | AO6: Nombre de jour de l'opération | AP6: Observations
A7: 1 | B7: =Saisie!B7 -> 0 | C7: =Saisie!C7 -> 0 | D7: =Saisie!D7 -> 0 | E7: =Saisie!E7 -> 0 | F7: =Saisie!F7 -> 0 | G7: =Saisie!G7 -> 0 | H7: =Saisie!I7 -> 0 | I7: =Saisie!J7 -> 0 | J7: =Saisie!K7 -> 0 | K7: =Saisie!L7 -> 0 | L7: =Saisie!L7 -> 0 | M7: =Saisie!#REF! -> #REF! | N7: =Saisie!#REF! -> #REF! | O7: {=_xlfn.IFS(Saisie!N7="OUI",1,Saisie!N7="NON",0)} -> #N/A | P7: =Saisie!#REF! -> #REF! | Q7: =Saisie!#REF! -> #REF! | R7: =Saisie!O7 -> 0 | S7: {=_xlfn.IFS(Saisie!#REF!="OUI",1,Saisie!#REF!="NON",0)} -> #REF! | T7: =Saisie!#REF! -> #REF! | U7: =Saisie!#REF! -> #REF! | V7: =Saisie!#REF! -> #REF! | W7: =Saisie!#REF! -> #REF! | X7: {=_xlfn.IFS(Saisie!#REF!="OUI",1,Saisie!#REF!="NON",0)} -> #REF! | Y7: {=_xlfn.IFS(Saisie!P7="OUI",1,Saisie!P7="NON",0)} -> #N/A | Z7: =Saisie!Q7 -> 0 | AA7: =Saisie!R7 -> 0 | AB7: {=_xlfn.IFS(Saisie!S7="OUI",1,Saisie!S7="NON",0)} -> #N/A | AC7: =Saisie!T7 -> 0 | AD7: =Saisie!U7 -> 0 | AE7: =Saisie!V7 -> 0 | AF7: =Saisie!W7 -> 0 | AG7: =Saisie!X7 -> 0 | AH7: =Saisie!Y7 -> 0 | AI7: =Saisie!Z7 -> 0 | AJ7: =Saisie!AA7 -> 0 | AK7: =Saisie!AB7 -> 0 | AL7: {=_xlfn.IFS(Saisie!AC7="OUI",1,Saisie!AC7="NON",0)} -> #N/A | AM7: {=_xlfn.IFS(Saisie!AD7="Complet",1,Saisie!AD7="Incomplet",0)} -> #N/A | AN7: =Saisie!AE7 -> 0 | AO7: =Saisie!AF7 -> 0
A8: 2 | B8: =Saisie!B8 -> 0 | C8: =Saisie!C8 -> 0 | D8: =Saisie!D8 -> 0 | E8: =Saisie!E8 -> 0 | F8: =Saisie!F8 -> 0 | G8: =Saisie!G8 -> 0 | H8: =Saisie!I8 -> 0 | I8: =Saisie!J8 -> 0 | J8: =Saisie!K8 -> 0 | K8: =Saisie!L8 -> 0 | L8: =Saisie!L8 -> 0 | M8: =Saisie!#REF! -> #REF! | N8: =Saisie!#REF! -> #REF! | O8: {=_xlfn.IFS(Saisie!N8="OUI",1,Saisie!N8="NON",0)} -> #N/A | P8: =Saisie!#REF! -> #REF! | Q8: =Saisie!#REF! -> #REF! | R8: =Saisie!O8 -> 0 | S8: {=_xlfn.IFS(Saisie!#REF!="OUI",1,Saisie!#REF!="NON",0)} -> #REF! | T8: =Saisie!#REF! -> #REF! | U8: =Saisie!#REF! -> #REF! | V8: =Saisie!#REF! -> #REF! | W8: =Saisie!#REF! -> #REF! | X8: {=_xlfn.IFS(Saisie!#REF!="OUI",1,Saisie!#REF!="NON",0)} -> #REF! | Y8: {=_xlfn.IFS(Saisie!P8="OUI",1,Saisie!P8="NON",0)} -> #N/A | Z8: =Saisie!Q8 -> 0 | AA8: =Saisie!R8 -> 0 | AB8: {=_xlfn.IFS(Saisie!S8="OUI",1,Saisie!S8="NON",0)} -> #N/A | AC8: =Saisie!T8 -> 0 | AD8: =Saisie!U8 -> 0 | AE8: =Saisie!V8 -> 0 | AF8: =Saisie!W8 -> 0 | AG8: =Saisie!X8 -> 0 | AH8: =Saisie!Y8 -> 0 | AI8: =Saisie!Z8 -> 0 | AJ8: =Saisie!AA8 -> 0 | AK8: =Saisie!AB8 -> 0 | AL8: {=_xlfn.IFS(Saisie!AC8="OUI",1,Saisie!AC8="NON",0)} -> #N/A | AM8: {=_xlfn.IFS(Saisie!AD8="Complet",1,Saisie!AD8="Incomplet",0)} -> #N/A | AN8: =Saisie!AE8 -> 0 | AO8: =Saisie!AF8 -> 0
A9: 3 | B9: =Saisie!B9 -> 0 | C9: =Saisie!C9 -> 0 | D9: =Saisie!D9 -> 0 | E9: =Saisie!E9 -> 0 | F9: =Saisie!F9 -> 0 | G9: =Saisie!G9 -> 0 | H9: =Saisie!I9 -> 0 | I9: =Saisie!J9 -> 0 | J9: =Saisie!K9 -> 0 | K9: =Saisie!L9 -> 0 | L9: =Saisie!L9 -> 0 | M9: =Saisie!#REF! -> #REF! | N9: =Saisie!#REF! -> #REF! | O9: {=_xlfn.IFS(Saisie!N9="OUI",1,Saisie!N9="NON",0)} -> #N/A | P9: =Saisie!#REF! -> #REF! | Q9: =Saisie!#REF! -> #REF! | R9: =Saisie!O9 -> 0 | S9: {=_xlfn.IFS(Saisie!#REF!="OUI",1,Saisie!#REF!="NON",0)} -> #REF! | T9: =Saisie!#REF! -> #REF! | U9: =Saisie!#REF! -> #REF! | V9: =Saisie!#REF! -> #REF! | W9: =Saisie!#REF! -> #REF! | X9: {=_xlfn.IFS(Saisie!#REF!="OUI",1,Saisie!#REF!="NON",0)} -> #REF! | Y9: {=_xlfn.IFS(Saisie!P9="OUI",1,Saisie!P9="NON",0)} -> #N/A | Z9: =Saisie!Q9 -> 0 | AA9: =Saisie!R9 -> 0 | AB9: {=_xlfn.IFS(Saisie!S9="OUI",1,Saisie!S9="NON",0)} -> #N/A | AC9: =Saisie!T9 -> 0 | AD9: =Saisie!U9 -> 0 | AE9: =Saisie!V9 -> 0 | AF9: =Saisie!W9 -> 0 | AG9: =Saisie!X9 -> 0 | AH9: =Saisie!Y9 -> 0 | AI9: =Saisie!Z9 -> 0 | AJ9: =Saisie!AA9 -> #REF! | AK9: =Saisie!AB9 -> 0 | AL9: {=_xlfn.IFS(Saisie!AC9="OUI",1,Saisie!AC9="NON",0)} -> #N/A | AM9: {=_xlfn.IFS(Saisie!AD9="Complet",1,Saisie!AD9="Incomplet",0)} -> #N/A | AN9: =Saisie!AE9 -> 0 | AO9: =Saisie!AF9 -> #REF!
A10: 4 | B10: =Saisie!B10 -> 0 | C10: =Saisie!C10 -> 0 | D10: =Saisie!D10 -> 0 | E10: =Saisie!E10 -> 0 | F10: =Saisie!F10 -> 0 | G10: =Saisie!G10 -> 0 | H10: =Saisie!I10 -> 0 | I10: =Saisie!J10 -> 0 | J10: =Saisie!K10 -> 0 | K10: =Saisie!L10 -> 0 | L10: =Saisie!L10 -> 0 | M10: =Saisie!#REF! -> #REF! | N10: =Saisie!#REF! -> #REF! | O10: {=_xlfn.IFS(Saisie!N10="OUI",1,Saisie!N10="NON",0)} -> #N/A | P10: =Saisie!#REF! -> #REF! | Q10: =Saisie!#REF! -> #REF! | R10: =Saisie!O10 -> 0 | S10: {=_xlfn.IFS(Saisie!#REF!="OUI",1,Saisie!#REF!="NON",0)} -> #REF! | T10: =Saisie!#REF! -> #REF! | U10: =Saisie!#REF! -> #REF! | V10: =Saisie!#REF! -> #REF! | W10: =Saisie!#REF! -> #REF! | X10: {=_xlfn.IFS(Saisie!#REF!="OUI",1,Saisie!#REF!="NON",0)} -> #REF! | Y10: {=_xlfn.IFS(Saisie!P10="OUI",1,Saisie!P10="NON",0)} -> #N/A | Z10: =Saisie!Q10 -> 0 | AA10: =Saisie!R10 -> 0 | AB10: {=_xlfn.IFS(Saisie!S10="OUI",1,Saisie!S10="NON",0)} -> #N/A | AC10: =Saisie!T10 -> 0 | AD10: =Saisie!U10 -> 0 | AE10: =Saisie!V10 -> 0 | AF10: =Saisie!W10 -> 0 | AG10: =Saisie!X10 -> 0 | AH10: =Saisie!Y10 -> 0 | AI10: =Saisie!Z10 -> 0 | AJ10: =Saisie!AA10 -> #REF! | AK10: =Saisie!AB10 -> 0 | AL10: {=_xlfn.IFS(Saisie!AC10="OUI",1,Saisie!AC10="NON",0)} -> #N/A | AM10: {=_xlfn.IFS(Saisie!AD10="Complet",1,Saisie!AD10="Incomplet",0)} -> #N/A | AN10: =Saisie!AE10 -> 0 | AO10: =Saisie!AF10 -> #REF!
A11: 5 | B11: =Saisie!B11 -> 0 | C11: =Saisie!C11 -> 0 | D11: =Saisie!D11 -> 0 | E11: =Saisie!E11 -> 0 | F11: =Saisie!F11 -> 0 | G11: =Saisie!G11 -> 0 | H11: =Saisie!I11 -> 0 | I11: =Saisie!J11 -> 0 | J11: =Saisie!K11 -> 0 | K11: =Saisie!L11 -> 0 | L11: =Saisie!L11 -> 0 | M11: =Saisie!#REF! -> #REF! | N11: =Saisie!#REF! -> #REF! | O11: {=_xlfn.IFS(Saisie!N11="OUI",1,Saisie!N11="NON",0)} -> #N/A | P11: =Saisie!#REF! -> #REF! | Q11: =Saisie!#REF! -> #REF! | R11: =Saisie!O11 -> 0 | S11: {=_xlfn.IFS(Saisie!#REF!="OUI",1,Saisie!#REF!="NON",0)} -> #REF! | T11: =Saisie!#REF! -> #REF! | U11: =Saisie!#REF! -> #REF! | V11: =Saisie!#REF! -> #REF! | W11: =Saisie!#REF! -> #REF! | X11: {=_xlfn.IFS(Saisie!#REF!="OUI",1,Saisie!#REF!="NON",0)} -> #REF! | Y11: {=_xlfn.IFS(Saisie!P11="OUI",1,Saisie!P11="NON",0)} -> #N/A | Z11: =Saisie!Q11 -> 0 | AA11: =Saisie!R11 -> 0 | AB11: {=_xlfn.IFS(Saisie!S11="OUI",1,Saisie!S11="NON",0)} -> #N/A | AC11: =Saisie!T11 -> 0 | AD11: =Saisie!U11 -> 0 | AE11: =Saisie!V11 -> 0 | AF11: =Saisie!W11 -> 0 | AG11: =Saisie!X11 -> 0 | AH11: =Saisie!Y11 -> 0 | AI11: =Saisie!Z11 -> 0 | AJ11: =Saisie!AA11 -> #REF! | AK11: =Saisie!AB11 -> 0 | AL11: {=_xlfn.IFS(Saisie!AC11="OUI",1,Saisie!AC11="NON",0)} -> #N/A | AM11: {=_xlfn.IFS(Saisie!AD11="Complet",1,Saisie!AD11="Incomplet",0)} -> #N/A | AN11: =Saisie!AE11 -> 0 | AO11: =Saisie!AF11 -> #REF!
A12: 6 | B12: =Saisie!B12 -> 0 | C12: =Saisie!C12 -> 0 | D12: =Saisie!D12 -> 0 | E12: =Saisie!E12 -> 0 | F12: =Saisie!F12 -> 0 | G12: =Saisie!G12 -> 0 | H12: =Saisie!I12 -> 0 | I12: =Saisie!J12 -> 0 | J12: =Saisie!K12 -> 0 | K12: =Saisie!L12 -> 0 | L12: =Saisie!L12 -> 0 | M12: =Saisie!#REF! -> #REF! | N12: =Saisie!#REF! -> #REF! | O12: {=_xlfn.IFS(Saisie!N12="OUI",1,Saisie!N12="NON",0)} -> #N/A | P12: =Saisie!#REF! -> #REF! | Q12: =Saisie!#REF! -> #REF! | R12: =Saisie!O12 -> 0 | S12: {=_xlfn.IFS(Saisie!#REF!="OUI",1,Saisie!#REF!="NON",0)} -> #REF! | T12: =Saisie!#REF! -> #REF! | U12: =Saisie!#REF! -> #REF! | V12: =Saisie!#REF! -> #REF! | W12: =Saisie!#REF! -> #REF! | X12: {=_xlfn.IFS(Saisie!#REF!="OUI",1,Saisie!#REF!="NON",0)} -> #REF! | Y12: {=_xlfn.IFS(Saisie!P12="OUI",1,Saisie!P12="NON",0)} -> #N/A | Z12: =Saisie!Q12 -> 0 | AA12: =Saisie!R12 -> 0 | AB12: {=_xlfn.IFS(Saisie!S12="OUI",1,Saisie!S12="NON",0)} -> #N/A | AC12: =Saisie!T12 -> 0 | AD12: =Saisie!U12 -> 0 | AE12: =Saisie!V12 -> 0 | AF12: =Saisie!W12 -> 0 | AG12: =Saisie!X12 -> 0 | AH12: =Saisie!Y12 -> 0 | AI12: =Saisie!Z12 -> 0 | AJ12: =Saisie!AA12 -> #REF! | AK12: =Saisie!AB12 -> 0 | AL12: {=_xlfn.IFS(Saisie!AC12="OUI",1,Saisie!AC12="NON",0)} -> #N/A | AM12: {=_xlfn.IFS(Saisie!AD12="Complet",1,Saisie!AD12="Incomplet",0)} -> #N/A | AN12: =Saisie!AE12 -> 0 | AO12: =Saisie!AF12 -> #REF!
A13: 7 | B13: =Saisie!B13 -> 0 | C13: =Saisie!C13 -> 0 | D13: =Saisie!D13 -> 0 | E13: =Saisie!E13 -> 0 | F13: =Saisie!F13 -> 0 | G13: =Saisie!G13 -> 0 | H13: =Saisie!I13 -> 0 | I13: =Saisie!J13 -> 0 | J13: =Saisie!K13 -> 0 | K13: =Saisie!L13 -> 0 | L13: =Saisie!L13 -> 0 | M13: =Saisie!#REF! -> #REF! | N13: =Saisie!#REF! -> #REF! | O13: {=_xlfn.IFS(Saisie!N13="OUI",1,Saisie!N13="NON",0)} -> #N/A | P13: =Saisie!#REF! -> #REF! | Q13: =Saisie!#REF! -> #REF! | R13: =Saisie!O13 -> 0 | S13: {=_xlfn.IFS(Saisie!#REF!="OUI",1,Saisie!#REF!="NON",0)} -> #REF! | T13: =Saisie!#REF! -> #REF! | U13: =Saisie!#REF! -> #REF! | V13: =Saisie!#REF! -> #REF! | W13: =Saisie!#REF! -> #REF! | X13: {=_xlfn.IFS(Saisie!#REF!="OUI",1,Saisie!#REF!="NON",0)} -> #REF! | Y13: {=_xlfn.IFS(Saisie!P13="OUI",1,Saisie!P13="NON",0)} -> #N/A | Z13: =Saisie!Q13 -> 0 | AA13: =Saisie!R13 -> 0 | AB13: {=_xlfn.IFS(Saisie!S13="OUI",1,Saisie!S13="NON",0)} -> #N/A | AC13: =Saisie!T13 -> 0 | AD13: =Saisie!U13 -> 0 | AE13: =Saisie!V13 -> 0 | AF13: =Saisie!W13 -> 0 | AG13: =Saisie!X13 -> 0 | AH13: =Saisie!Y13 -> 0 | AI13: =Saisie!Z13 -> 0 | AJ13: =Saisie!AA13 -> #REF! | AK13: =Saisie!AB13 -> 0 | AL13: {=_xlfn.IFS(Saisie!AC13="OUI",1,Saisie!AC13="NON",0)} -> #N/A | AM13: {=_xlfn.IFS(Saisie!AD13="Complet",1,Saisie!AD13="Incomplet",0)} -> #N/A | AN13: =Saisie!AE13 -> 0 | AO13: =Saisie!AF13 -> #REF!
A14: 8 | B14: =Saisie!B14 -> 0 | C14: =Saisie!C14 -> 0 | D14: =Saisie!D14 -> 0 | E14: =Saisie!E14 -> 0 | F14: =Saisie!F14 -> 0 | G14: =Saisie!G14 -> 0 | H14: =Saisie!I14 -> 0 | I14: =Saisie!J14 -> 0 | J14: =Saisie!K14 -> 0 | K14: =Saisie!L14 -> 0 | L14: =Saisie!L14 -> 0 | M14: =Saisie!#REF! -> #REF! | N14: =Saisie!#REF! -> #REF! | O14: {=_xlfn.IFS(Saisie!N14="OUI",1,Saisie!N14="NON",0)} -> #N/A | P14: =Saisie!#REF! -> #REF! | Q14: =Saisie!#REF! -> #REF! | R14: =Saisie!O14 -> 0 | S14: {=_xlfn.IFS(Saisie!#REF!="OUI",1,Saisie!#REF!="NON",0)} -> #REF! | T14: =Saisie!#REF! -> #REF! | U14: =Saisie!#REF! -> #REF! | V14: =Saisie!#REF! -> #REF! | W14: =Saisie!#REF! -> #REF! | X14: {=_xlfn.IFS(Saisie!#REF!="OUI",1,Saisie!#REF!="NON",0)} -> #REF! | Y14: {=_xlfn.IFS(Saisie!P14="OUI",1,Saisie!P14="NON",0)} -> #N/A | Z14: =Saisie!Q14 -> 0 | AA14: =Saisie!R14 -> 0 | AB14: {=_xlfn.IFS(Saisie!S14="OUI",1,Saisie!S14="NON",0)} -> #N/A | AC14: =Saisie!T14 -> 0 | AD14: =Saisie!U14 -> 0 | AE14: =Saisie!V14 -> 0 | AF14: =Saisie!W14 -> 0 | AG14: =Saisie!X14 -> 0 | AH14: =Saisie!Y14 -> 0 | AI14: =Saisie!Z14 -> 0 | AJ14: =Saisie!AA14 -> #REF! | AK14: =Saisie!AB14 -> 0 | AL14: {=_xlfn.IFS(Saisie!AC14="OUI",1,Saisie!AC14="NON",0)} -> #N/A | AM14: {=_xlfn.IFS(Saisie!AD14="Complet",1,Saisie!AD14="Incomplet",0)} -> #N/A | AN14: =Saisie!AE14 -> 0 | AO14: =Saisie!AF14 -> #REF!
A15: 9 | B15: =Saisie!B15 -> 0 | C15: =Saisie!C15 -> 0 | D15: =Saisie!D15 -> 0 | E15: =Saisie!E15 -> 0 | F15: =Saisie!F15 -> 0 | G15: =Saisie!G15 -> 0 | H15: =Saisie!I15 -> 0 | I15: =Saisie!J15 -> 0 | J15: =Saisie!K15 -> 0 | K15: =Saisie!L15 -> 0 | L15: =Saisie!L15 -> 0 | M15: =Saisie!#REF! -> #REF! | N15: =Saisie!#REF! -> #REF! | O15: {=_xlfn.IFS(Saisie!N15="OUI",1,Saisie!N15="NON",0)} -> #N/A | P15: =Saisie!#REF! -> #REF! | Q15: =Saisie!#REF! -> #REF! | R15: =Saisie!O15 -> 0 | S15: {=_xlfn.IFS(Saisie!#REF!="OUI",1,Saisie!#REF!="NON",0)} -> #REF! | T15: =Saisie!#REF! -> #REF! | U15: =Saisie!#REF! -> #REF! | V15: =Saisie!#REF! -> #REF! | W15: =Saisie!#REF! -> #REF! | X15: {=_xlfn.IFS(Saisie!#REF!="OUI",1,Saisie!#REF!="NON",0)} -> #REF! | Y15: {=_xlfn.IFS(Saisie!P15="OUI",1,Saisie!P15="NON",0)} -> #N/A | Z15: =Saisie!Q15 -> 0 | AA15: =Saisie!R15 -> 0 | AB15: {=_xlfn.IFS(Saisie!S15="OUI",1,Saisie!S15="NON",0)} -> #N/A | AC15: =Saisie!T15 -> 0 | AD15: =Saisie!U15 -> 0 | AE15: =Saisie!V15 -> 0 | AF15: =Saisie!W15 -> 0 | AG15: =Saisie!X15 -> 0 | AH15: =Saisie!Y15 -> 0 | AI15: =Saisie!Z15 -> 0 | AJ15: =Saisie!AA15 -> #REF! | AK15: =Saisie!AB15 -> 0 | AL15: {=_xlfn.IFS(Saisie!AC15="OUI",1,Saisie!AC15="NON",0)} -> #N/A | AM15: {=_xlfn.IFS(Saisie!AD15="Complet",1,Saisie!AD15="Incomplet",0)} -> #N/A | AN15: =Saisie!AE15 -> 0 | AO15: =Saisie!AF15 -> #REF!
A16: 10 | B16: =Saisie!B16 -> 0 | C16: =Saisie!C16 -> 0 | D16: =Saisie!D16 -> 0 | E16: =Saisie!E16 -> 0 | F16: =Saisie!F16 -> 0 | G16: =Saisie!G16 -> 0 | H16: =Saisie!I16 -> 0 | I16: =Saisie!J16 -> 0 | J16: =Saisie!K16 -> 0 | K16: =Saisie!L16 -> 0 | L16: =Saisie!L16 -> 0 | M16: =Saisie!#REF! -> #REF! | N16: =Saisie!#REF! -> #REF! | O16: {=_xlfn.IFS(Saisie!N16="OUI",1,Saisie!N16="NON",0)} -> #N/A | P16: =Saisie!#REF! -> #REF! | Q16: =Saisie!#REF! -> #REF! | R16: =Saisie!O16 -> 0 | S16: {=_xlfn.IFS(Saisie!#REF!="OUI",1,Saisie!#REF!="NON",0)} -> #REF! | T16: =Saisie!#REF! -> #REF! | U16: =Saisie!#REF! -> #REF! | V16: =Saisie!#REF! -> #REF! | W16: =Saisie!#REF! -> #REF! | X16: {=_xlfn.IFS(Saisie!#REF!="OUI",1,Saisie!#REF!="NON",0)} -> #REF! | Y16: {=_xlfn.IFS(Saisie!P16="OUI",1,Saisie!P16="NON",0)} -> #N/A | Z16: =Saisie!Q16 -> 0 | AA16: =Saisie!R16 -> 0 | AB16: {=_xlfn.IFS(Saisie!S16="OUI",1,Saisie!S16="NON",0)} -> #N/A | AC16: =Saisie!T16 -> 0 | AD16: =Saisie!U16 -> 0 | AE16: =Saisie!V16 -> 0 | AF16: =Saisie!W16 -> 0 | AG16: =Saisie!X16 -> 0 | AH16: =Saisie!Y16 -> 0 | AI16: =Saisie!Z16 -> 0 | AJ16: =Saisie!AA16 -> #REF! | AK16: =Saisie!AB16 -> 0 | AL16: {=_xlfn.IFS(Saisie!AC16="OUI",1,Saisie!AC16="NON",0)} -> #N/A | AM16: {=_xlfn.IFS(Saisie!AD16="Complet",1,Saisie!AD16="Incomplet",0)} -> #N/A | AN16: =Saisie!AE16 -> 0 | AO16: =Saisie!AF16 -> #REF!
A17: 11 | B17: =Saisie!B17 -> 0 | C17: =Saisie!C17 -> 0 | D17: =Saisie!D17 -> 0 | E17: =Saisie!E17 -> 0 | F17: =Saisie!F17 -> 0 | G17: =Saisie!G17 -> 0 | H17: =Saisie!I17 -> 0 | I17: =Saisie!J17 -> 0 | J17: =Saisie!K17 -> 0 | K17: =Saisie!L17 -> 0 | L17: =Saisie!L17 -> 0 | M17: =Saisie!#REF! -> #REF! | N17: =Saisie!#REF! -> #REF! | O17: {=_xlfn.IFS(Saisie!N17="OUI",1,Saisie!N17="NON",0)} -> #N/A | P17: =Saisie!#REF! -> #REF! | Q17: =Saisie!#REF! -> #REF! | R17: =Saisie!O17 -> 0 | S17: {=_xlfn.IFS(Saisie!#REF!="OUI",1,Saisie!#REF!="NON",0)} -> #REF! | T17: =Saisie!#REF! -> #REF! | U17: =Saisie!#REF! -> #REF! | V17: =Saisie!#REF! -> #REF! | W17: =Saisie!#REF! -> #REF! | X17: {=_xlfn.IFS(Saisie!#REF!="OUI",1,Saisie!#REF!="NON",0)} -> #REF! | Y17: {=_xlfn.IFS(Saisie!P17="OUI",1,Saisie!P17="NON",0)} -> #N/A | Z17: =Saisie!Q17 -> 0 | AA17: =Saisie!R17 -> 0 | AB17: {=_xlfn.IFS(Saisie!S17="OUI",1,Saisie!S17="NON",0)} -> #N/A | AC17: =Saisie!T17 -> 0 | AD17: =Saisie!U17 -> 0 | AE17: =Saisie!V17 -> 0 | AF17: =Saisie!W17 -> 0 | AG17: =Saisie!X17 -> 0 | AH17: =Saisie!Y17 -> 0 | AI17: =Saisie!Z17 -> 0 | AJ17: =Saisie!AA17 -> #REF! | AK17: =Saisie!AB17 -> 0 | AL17: {=_xlfn.IFS(Saisie!AC17="OUI",1,Saisie!AC17="NON",0)} -> #N/A | AM17: {=_xlfn.IFS(Saisie!AD17="Complet",1,Saisie!AD17="Incomplet",0)} -> #N/A | AN17: =Saisie!AE17 -> 0 | AO17: =Saisie!AF17 -> #REF!
A18: 12 | B18: =Saisie!B18 -> 0 | C18: =Saisie!C18 -> 0 | D18: =Saisie!D18 -> 0 | E18: =Saisie!E18 -> 0 | F18: =Saisie!F18 -> 0 | G18: =Saisie!G18 -> 0 | H18: =Saisie!I18 -> 0 | I18: =Saisie!J18 -> 0 | J18: =Saisie!K18 -> 0 | K18: =Saisie!L18 -> 0 | L18: =Saisie!L18 -> 0 | M18: =Saisie!#REF! -> #REF! | N18: =Saisie!#REF! -> #REF! | O18: {=_xlfn.IFS(Saisie!N18="OUI",1,Saisie!N18="NON",0)} -> #N/A | P18: =Saisie!#REF! -> #REF! | Q18: =Saisie!#REF! -> #REF! | R18: =Saisie!O18 -> 0 | S18: {=_xlfn.IFS(Saisie!#REF!="OUI",1,Saisie!#REF!="NON",0)} -> #REF! | T18: =Saisie!#REF! -> #REF! | U18: =Saisie!#REF! -> #REF! | V18: =Saisie!#REF! -> #REF! | W18: =Saisie!#REF! -> #REF! | X18: {=_xlfn.IFS(Saisie!#REF!="OUI",1,Saisie!#REF!="NON",0)} -> #REF! | Y18: {=_xlfn.IFS(Saisie!P18="OUI",1,Saisie!P18="NON",0)} -> #N/A | Z18: =Saisie!Q18 -> 0 | AA18: =Saisie!R18 -> 0 | AB18: {=_xlfn.IFS(Saisie!S18="OUI",1,Saisie!S18="NON",0)} -> #N/A | AC18: =Saisie!T18 -> 0 | AD18: =Saisie!U18 -> 0 | AE18: =Saisie!V18 -> 0 | AF18: =Saisie!W18 -> 0 | AG18: =Saisie!X18 -> 0 | AH18: =Saisie!Y18 -> 0 | AI18: =Saisie!Z18 -> 0 | AJ18: =Saisie!AA18 -> #REF! | AK18: =Saisie!AB18 -> 0 | AL18: {=_xlfn.IFS(Saisie!AC18="OUI",1,Saisie!AC18="NON",0)} -> #N/A | AM18: {=_xlfn.IFS(Saisie!AD18="Complet",1,Saisie!AD18="Incomplet",0)} -> #N/A | AN18: =Saisie!AE18 -> 0 | AO18: =Saisie!AF18 -> #REF!
... A125: 119 | B125: =Saisie!B125 -> 0 | C125: =Saisie!C125 -> 0 | D125: =Saisie!D125 -> 0 | E125: =Saisie!E125 -> 0 | F125: =Saisie!F125 -> 0 | G125: =Saisie!G125 -> 0 | H125: =Saisie!I125 -> 0 | I125: =Saisie!J125 -> 0 | J125: =Saisie!K125 -> 0 | K125: =Saisie!L125 -> 0 | L125: =Saisie!L125 -> 0 | M125: =Saisie!#REF! -> #REF! | N125: =Saisie!#REF! -> #REF! | O125: {=_xlfn.IFS(Saisie!N125="OUI",1,Saisie!N125="NON",0)} -> #N/A | P125: =Saisie!#REF! -> #REF! | Q125: =Saisie!#REF! -> #REF! | R125: =Saisie!O125 -> 0 | S125: {=_xlfn.IFS(Saisie!#REF!="OUI",1,Saisie!#REF!="NON",0)} -> #REF! | T125: =Saisie!#REF! -> #REF! | U125: =Saisie!#REF! -> #REF! | V125: =Saisie!#REF! -> #REF! | W125: =Saisie!#REF! -> #REF! | X125: {=_xlfn.IFS(Saisie!#REF!="OUI",1,Saisie!#REF!="NON",0)} -> #REF! | Y125: {=_xlfn.IFS(Saisie!P125="OUI",1,Saisie!P125="NON",0)} -> #N/A | Z125: =Saisie!Q125 -> 0 | AA125: =Saisie!R125 -> 0 | AB125: {=_xlfn.IFS(Saisie!S125="OUI",1,Saisie!S125="NON",0)} -> #N/A | AC125: =Saisie!T125 -> 0 | AD125: =Saisie!U125 -> 0 | AE125: =Saisie!V125 -> 0 | AF125: =Saisie!W125 -> 0 | AG125: =Saisie!X125 -> 0 | AH125: =Saisie!Y125 -> 0 | AI125: =Saisie!Z125 -> 0 | AJ125: =Saisie!AA125 -> #REF! | AK125: =Saisie!AB125 -> 0 | AL125: {=_xlfn.IFS(Saisie!AC125="OUI",1,Saisie!AC125="NON",0)} -> #N/A | AM125: {=_xlfn.IFS(Saisie!AD125="Complet",1,Saisie!AD125="Incomplet",0)} -> #N/A | AN125: =Saisie!AE125 -> 0 | AO125: =Saisie!AF125 -> 0
A126: 120 | B126: =Saisie!B126 -> 0 | C126: =Saisie!C126 -> 0 | D126: =Saisie!D126 -> 0 | E126: =Saisie!E126 -> 0 | F126: =Saisie!F126 -> 0 | G126: =Saisie!G126 -> 0 | H126: =Saisie!I126 -> 0 | I126: =Saisie!J126 -> 0 | J126: =Saisie!K126 -> 0 | K126: =Saisie!L126 -> 0 | L126: =Saisie!L126 -> 0 | M126: =Saisie!#REF! -> #REF! | N126: =Saisie!#REF! -> #REF! | O126: {=_xlfn.IFS(Saisie!N126="OUI",1,Saisie!N126="NON",0)} -> #N/A | P126: =Saisie!#REF! -> #REF! | Q126: =Saisie!#REF! -> #REF! | R126: =Saisie!O126 -> 0 | S126: {=_xlfn.IFS(Saisie!#REF!="OUI",1,Saisie!#REF!="NON",0)} -> #REF! | T126: =Saisie!#REF! -> #REF! | U126: =Saisie!#REF! -> #REF! | V126: =Saisie!#REF! -> #REF! | W126: =Saisie!#REF! -> #REF! | X126: {=_xlfn.IFS(Saisie!#REF!="OUI",1,Saisie!#REF!="NON",0)} -> #REF! | Y126: {=_xlfn.IFS(Saisie!P126="OUI",1,Saisie!P126="NON",0)} -> #N/A | Z126: =Saisie!Q126 -> 0 | AA126: =Saisie!R126 -> 0 | AB126: {=_xlfn.IFS(Saisie!S126="OUI",1,Saisie!S126="NON",0)} -> #N/A | AC126: =Saisie!T126 -> 0 | AD126: =Saisie!U126 -> 0 | AE126: =Saisie!V126 -> 0 | AF126: =Saisie!W126 -> 0 | AG126: =Saisie!X126 -> 0 | AH126: =Saisie!Y126 -> 0 | AI126: =Saisie!Z126 -> 0 | AJ126: =Saisie!AA126 -> #REF! | AK126: =Saisie!AB126 -> 0 | AL126: {=_xlfn.IFS(Saisie!AC126="OUI",1,Saisie!AC126="NON",0)} -> #N/A | AM126: {=_xlfn.IFS(Saisie!AD126="Complet",1,Saisie!AD126="Incomplet",0)} -> #N/A | AN126: =Saisie!AE126 -> 0 | AO126: =Saisie!AF126 -> 0 | AP126: Logiquement ne devrait pas passé en PSD
A127: 121 | B127: =Saisie!B127 -> 0 | C127: =Saisie!C127 -> 0 | D127: =Saisie!D127 -> 0 | E127: =Saisie!E127 -> 0 | F127: =Saisie!F127 -> 0 | G127: =Saisie!G127 -> 0 | H127: =Saisie!I127 -> 0 | I127: =Saisie!J127 -> 0 | J127: =Saisie!K127 -> 0 | K127: =Saisie!L127 -> 0 | L127: =Saisie!L127 -> 0 | M127: =Saisie!#REF! -> #REF! | N127: =Saisie!#REF! -> #REF! | O127: {=_xlfn.IFS(Saisie!N127="OUI",1,Saisie!N127="NON",0)} -> #N/A | P127: =Saisie!#REF! -> #REF! | Q127: =Saisie!#REF! -> #REF! | R127: =Saisie!O127 -> 0 | S127: {=_xlfn.IFS(Saisie!#REF!="OUI",1,Saisie!#REF!="NON",0)} -> #REF! | T127: =Saisie!#REF! -> #REF! | U127: =Saisie!#REF! -> #REF! | V127: =Saisie!#REF! -> #REF! | W127: =Saisie!#REF! -> #REF! | X127: {=_xlfn.IFS(Saisie!#REF!="OUI",1,Saisie!#REF!="NON",0)} -> #REF! | Y127: {=_xlfn.IFS(Saisie!P127="OUI",1,Saisie!P127="NON",0)} -> #N/A | Z127: =Saisie!Q127 -> 0 | AA127: =Saisie!R127 -> 0 | AB127: {=_xlfn.IFS(Saisie!S127="OUI",1,Saisie!S127="NON",0)} -> #N/A | AC127: =Saisie!T127 -> 0 | AD127: =Saisie!U127 -> 0 | AE127: =Saisie!V127 -> 0 | AF127: =Saisie!W127 -> 0 | AG127: =Saisie!X127 -> 0 | AH127: =Saisie!Y127 -> 0 | AI127: =Saisie!Z127 -> 0 | AJ127: =Saisie!AA127 -> #REF! | AK127: =Saisie!AB127 -> 0 | AL127: {=_xlfn.IFS(Saisie!AC127="OUI",1,Saisie!AC127="NON",0)} -> #N/A | AM127: {=_xlfn.IFS(Saisie!AD127="Complet",1,Saisie!AD127="Incomplet",0)} -> #N/A | AN127: =Saisie!AE127 -> 0 | AO127: =Saisie!AF127 -> 0
A128: 122 | B128: =Saisie!B128 -> 0 | C128: =Saisie!C128 -> 0 | D128: =Saisie!D128 -> 0 | E128: =Saisie!E128 -> 0 | F128: =Saisie!F128 -> 0 | G128: =Saisie!G128 -> 0 | H128: =Saisie!I128 -> 0 | I128: =Saisie!J128 -> 0 | J128: =Saisie!K128 -> 0 | K128: =Saisie!L128 -> 0 | L128: =Saisie!L128 -> 0 | M128: =Saisie!#REF! -> #REF! | N128: =Saisie!#REF! -> #REF! | O128: {=_xlfn.IFS(Saisie!N128="OUI",1,Saisie!N128="NON",0)} -> #N/A | P128: =Saisie!#REF! -> #REF! | Q128: =Saisie!#REF! -> #REF! | R128: =Saisie!O128 -> 0 | S128: {=_xlfn.IFS(Saisie!#REF!="OUI",1,Saisie!#REF!="NON",0)} -> #REF! | T128: =Saisie!#REF! -> #REF! | U128: =Saisie!#REF! -> #REF! | V128: =Saisie!#REF! -> #REF! | W128: =Saisie!#REF! -> #REF! | X128: {=_xlfn.IFS(Saisie!#REF!="OUI",1,Saisie!#REF!="NON",0)} -> #REF! | Y128: {=_xlfn.IFS(Saisie!P128="OUI",1,Saisie!P128="NON",0)} -> #N/A | Z128: =Saisie!Q128 -> 0 | AA128: =Saisie!R128 -> 0 | AB128: {=_xlfn.IFS(Saisie!S128="OUI",1,Saisie!S128="NON",0)} -> #N/A | AC128: =Saisie!T128 -> 0 | AD128: =Saisie!U128 -> 0 | AE128: =Saisie!V128 -> 0 | AF128: =Saisie!W128 -> 0 | AG128: =Saisie!X128 -> 0 | AH128: =Saisie!Y128 -> 0 | AI128: =Saisie!Z128 -> 0 | AJ128: =Saisie!AA128 -> #REF! | AK128: =Saisie!AB128 -> 0 | AL128: {=_xlfn.IFS(Saisie!AC128="OUI",1,Saisie!AC128="NON",0)} -> #N/A | AM128: {=_xlfn.IFS(Saisie!AD128="Complet",1,Saisie!AD128="Incomplet",0)} -> #N/A | AN128: =Saisie!AE128 -> 0 | AO128: =Saisie!AF128 -> 0
A129: 123 | B129: =Saisie!B129 -> 0 | C129: =Saisie!C129 -> 0 | D129: =Saisie!D129 -> 0 | E129: =Saisie!E129 -> 0 | F129: =Saisie!F129 -> 0 | G129: =Saisie!G129 -> 0 | H129: =Saisie!I129 -> 0 | I129: =Saisie!J129 -> 0 | J129: =Saisie!K129 -> 0 | K129: =Saisie!L129 -> 0 | L129: =Saisie!L129 -> 0 | M129: =Saisie!#REF! -> #REF! | N129: =Saisie!#REF! -> #REF! | O129: {=_xlfn.IFS(Saisie!N129="OUI",1,Saisie!N129="NON",0)} -> #N/A | P129: =Saisie!#REF! -> #REF! | Q129: =Saisie!#REF! -> #REF! | R129: =Saisie!O129 -> 0 | S129: {=_xlfn.IFS(Saisie!#REF!="OUI",1,Saisie!#REF!="NON",0)} -> #REF! | T129: =Saisie!#REF! -> #REF! | U129: =Saisie!#REF! -> #REF! | V129: =Saisie!#REF! -> #REF! | W129: =Saisie!#REF! -> #REF! | X129: {=_xlfn.IFS(Saisie!#REF!="OUI",1,Saisie!#REF!="NON",0)} -> #REF! | Y129: {=_xlfn.IFS(Saisie!P129="OUI",1,Saisie!P129="NON",0)} -> #N/A | Z129: =Saisie!Q129 -> 0 | AA129: =Saisie!R129 -> 0 | AB129: {=_xlfn.IFS(Saisie!S129="OUI",1,Saisie!S129="NON",0)} -> #N/A | AC129: =Saisie!T129 -> 0 | AD129: =Saisie!U129 -> 0 | AE129: =Saisie!V129 -> 0 | AF129: =Saisie!W129 -> 0 | AG129: =Saisie!X129 -> 0 | AH129: =Saisie!Y129 -> 0 | AI129: =Saisie!Z129 -> 0 | AJ129: =Saisie!AA129 -> #REF! | AK129: =Saisie!AB129 -> 0 | AL129: {=_xlfn.IFS(Saisie!AC129="OUI",1,Saisie!AC129="NON",0)} -> #N/A | AM129: {=_xlfn.IFS(Saisie!AD129="Complet",1,Saisie!AD129="Incomplet",0)} -> #N/A | AN129: =Saisie!AE129 -> 0 | AO129: =Saisie!AF129 -> 0
A130: 124 | B130: =Saisie!B130 -> 0 | C130: =Saisie!C130 -> 0 | D130: =Saisie!D130 -> 0 | E130: =Saisie!E130 -> 0 | F130: =Saisie!F130 -> 0 | G130: =Saisie!G130 -> 0 | H130: =Saisie!I130 -> 0 | I130: =Saisie!J130 -> 0 | J130: =Saisie!K130 -> 0 | K130: =Saisie!L130 -> 0 | L130: =Saisie!L130 -> 0 | M130: =Saisie!#REF! -> #REF! | N130: =Saisie!#REF! -> #REF! | O130: {=_xlfn.IFS(Saisie!N130="OUI",1,Saisie!N130="NON",0)} -> #N/A | P130: =Saisie!#REF! -> #REF! | Q130: =Saisie!#REF! -> #REF! | R130: =Saisie!O130 -> 0 | S130: {=_xlfn.IFS(Saisie!#REF!="OUI",1,Saisie!#REF!="NON",0)} -> #REF! | T130: =Saisie!#REF! -> #REF! | U130: =Saisie!#REF! -> #REF! | V130: =Saisie!#REF! -> #REF! | W130: =Saisie!#REF! -> #REF! | X130: {=_xlfn.IFS(Saisie!#REF!="OUI",1,Saisie!#REF!="NON",0)} -> #REF! | Y130: {=_xlfn.IFS(Saisie!P130="OUI",1,Saisie!P130="NON",0)} -> #N/A | Z130: =Saisie!Q130 -> 0 | AA130: =Saisie!R130 -> 0 | AB130: {=_xlfn.IFS(Saisie!S130="OUI",1,Saisie!S130="NON",0)} -> #N/A | AC130: =Saisie!T130 -> 0 | AD130: =Saisie!U130 -> 0 | AE130: =Saisie!V130 -> 0 | AF130: =Saisie!W130 -> 0 | AG130: =Saisie!X130 -> 0 | AH130: =Saisie!Y130 -> 0 | AI130: =Saisie!Z130 -> 0 | AJ130: =Saisie!AA130 -> #REF! | AK130: =Saisie!AB130 -> 0 | AL130: {=_xlfn.IFS(Saisie!AC130="OUI",1,Saisie!AC130="NON",0)} -> #N/A | AM130: {=_xlfn.IFS(Saisie!AD130="Complet",1,Saisie!AD130="Incomplet",0)} -> #N/A | AN130: =Saisie!AE130 -> 0 | AO130: =Saisie!AF130 -> 0
A131: 125 | B131: =Saisie!B131 -> 0 | C131: =Saisie!C131 -> 0 | D131: =Saisie!D131 -> 0 | E131: =Saisie!E131 -> 0 | F131: =Saisie!F131 -> 0 | G131: =Saisie!G131 -> 0 | H131: =Saisie!I131 -> 0 | I131: =Saisie!J131 -> 0 | J131: =Saisie!K131 -> 0 | K131: =Saisie!L131 -> 0 | L131: =Saisie!L131 -> 0 | M131: =Saisie!#REF! -> #REF! | N131: =Saisie!#REF! -> #REF! | O131: {=_xlfn.IFS(Saisie!N131="OUI",1,Saisie!N131="NON",0)} -> #N/A | P131: =Saisie!#REF! -> #REF! | Q131: =Saisie!#REF! -> #REF! | R131: =Saisie!O131 -> 0 | S131: {=_xlfn.IFS(Saisie!#REF!="OUI",1,Saisie!#REF!="NON",0)} -> #REF! | T131: =Saisie!#REF! -> #REF! | U131: =Saisie!#REF! -> #REF! | V131: =Saisie!#REF! -> #REF! | W131: =Saisie!#REF! -> #REF! | X131: {=_xlfn.IFS(Saisie!#REF!="OUI",1,Saisie!#REF!="NON",0)} -> #REF! | Y131: {=_xlfn.IFS(Saisie!P131="OUI",1,Saisie!P131="NON",0)} -> #N/A | Z131: =Saisie!Q131 -> 0 | AA131: =Saisie!R131 -> 0 | AB131: {=_xlfn.IFS(Saisie!S131="OUI",1,Saisie!S131="NON",0)} -> #N/A | AC131: =Saisie!T131 -> 0 | AD131: =Saisie!U131 -> 0 | AE131: =Saisie!V131 -> 0 | AF131: =Saisie!W131 -> 0 | AG131: =Saisie!X131 -> 0 | AH131: =Saisie!Y131 -> 0 | AI131: =Saisie!Z131 -> 0 | AJ131: =Saisie!AA131 -> #REF! | AK131: =Saisie!AB131 -> 0 | AL131: {=_xlfn.IFS(Saisie!AC131="OUI",1,Saisie!AC131="NON",0)} -> #N/A | AM131: {=_xlfn.IFS(Saisie!AD131="Complet",1,Saisie!AD131="Incomplet",0)} -> #N/A | AN131: =Saisie!AE131 -> 0 | AO131: =Saisie!AF131 -> 0
A132: 126 | B132: =Saisie!B132 -> 0 | C132: =Saisie!C132 -> 0 | D132: =Saisie!D132 -> 0 | E132: =Saisie!E132 -> 0 | F132: =Saisie!F132 -> 0 | G132: =Saisie!G132 -> 0 | H132: =Saisie!I132 -> 0 | I132: =Saisie!J132 -> 0 | J132: =Saisie!K132 -> 0 | K132: =Saisie!L132 -> 0 | L132: =Saisie!L132 -> 0 | M132: =Saisie!#REF! -> #REF! | N132: =Saisie!#REF! -> #REF! | O132: {=_xlfn.IFS(Saisie!N132="OUI",1,Saisie!N132="NON",0)} -> #N/A | P132: =Saisie!#REF! -> #REF! | Q132: =Saisie!#REF! -> #REF! | R132: =Saisie!O132 -> 0 | S132: {=_xlfn.IFS(Saisie!#REF!="OUI",1,Saisie!#REF!="NON",0)} -> #REF! | T132: =Saisie!#REF! -> #REF! | U132: =Saisie!#REF! -> #REF! | V132: =Saisie!#REF! -> #REF! | W132: =Saisie!#REF! -> #REF! | X132: {=_xlfn.IFS(Saisie!#REF!="OUI",1,Saisie!#REF!="NON",0)} -> #REF! | Y132: {=_xlfn.IFS(Saisie!P132="OUI",1,Saisie!P132="NON",0)} -> #N/A | Z132: =Saisie!Q132 -> 0 | AA132: =Saisie!R132 -> 0 | AB132: {=_xlfn.IFS(Saisie!S132="OUI",1,Saisie!S132="NON",0)} -> #N/A | AC132: =Saisie!T132 -> 0 | AD132: =Saisie!U132 -> 0 | AE132: =Saisie!V132 -> 0 | AF132: =Saisie!W132 -> 0 | AG132: =Saisie!X132 -> 0 | AH132: =Saisie!Y132 -> 0 | AI132: =Saisie!Z132 -> 0 | AJ132: =Saisie!AA132 -> #REF! | AK132: =Saisie!AB132 -> 0 | AL132: {=_xlfn.IFS(Saisie!AC132="OUI",1,Saisie!AC132="NON",0)} -> #N/A | AM132: {=_xlfn.IFS(Saisie!AD132="Complet",1,Saisie!AD132="Incomplet",0)} -> #N/A | AN132: =Saisie!AE132 -> 0 | AO132: =Saisie!AF132 -> 0
A133: 127 | B133: =Saisie!B133 -> 0 | C133: =Saisie!C133 -> 0 | D133: =Saisie!D133 -> 0 | E133: =Saisie!E133 -> 0 | F133: =Saisie!F133 -> 0 | G133: =Saisie!G133 -> 0 | H133: =Saisie!I133 -> 0 | I133: =Saisie!J133 -> 0 | J133: =Saisie!K133 -> 0 | K133: =Saisie!L133 -> 0 | L133: =Saisie!L133 -> 0 | M133: =Saisie!#REF! -> #REF! | N133: =Saisie!#REF! -> #REF! | O133: {=_xlfn.IFS(Saisie!N133="OUI",1,Saisie!N133="NON",0)} -> #N/A | P133: =Saisie!#REF! -> #REF! | Q133: =Saisie!#REF! -> #REF! | R133: =Saisie!O133 -> 0 | S133: {=_xlfn.IFS(Saisie!#REF!="OUI",1,Saisie!#REF!="NON",0)} -> #REF! | T133: =Saisie!#REF! -> #REF! | U133: =Saisie!#REF! -> #REF! | V133: =Saisie!#REF! -> #REF! | W133: =Saisie!#REF! -> #REF! | X133: {=_xlfn.IFS(Saisie!#REF!="OUI",1,Saisie!#REF!="NON",0)} -> #REF! | Y133: {=_xlfn.IFS(Saisie!P133="OUI",1,Saisie!P133="NON",0)} -> #N/A | Z133: =Saisie!Q133 -> 0 | AA133: =Saisie!R133 -> 0 | AB133: {=_xlfn.IFS(Saisie!S133="OUI",1,Saisie!S133="NON",0)} -> #N/A | AC133: =Saisie!T133 -> 0 | AD133: =Saisie!U133 -> 0 | AE133: =Saisie!V133 -> 0 | AF133: =Saisie!W133 -> 0 | AG133: =Saisie!X133 -> 0 | AH133: =Saisie!Y133 -> 0 | AI133: =Saisie!Z133 -> 0 | AJ133: =Saisie!AA133 -> #REF! | AK133: =Saisie!AB133 -> 0 | AL133: {=_xlfn.IFS(Saisie!AC133="OUI",1,Saisie!AC133="NON",0)} -> #N/A | AM133: {=_xlfn.IFS(Saisie!AD133="Complet",1,Saisie!AD133="Incomplet",0)} -> #N/A | AN133: =Saisie!AE133 -> 0 | AO133: =Saisie!AF133 -> 0
A134: 128 | B134: =Saisie!B134 -> 0 | C134: =Saisie!C134 -> 0 | D134: =Saisie!D134 -> 0 | E134: =Saisie!E134 -> 0 | F134: =Saisie!F134 -> 0 | G134: =Saisie!G134 -> 0 | H134: =Saisie!I134 -> 0 | I134: =Saisie!J134 -> 0 | J134: =Saisie!K134 -> 0 | K134: =Saisie!L134 -> 0 | L134: =Saisie!L134 -> 0 | M134: =Saisie!#REF! -> #REF! | N134: =Saisie!#REF! -> #REF! | O134: {=_xlfn.IFS(Saisie!N134="OUI",1,Saisie!N134="NON",0)} -> #N/A | P134: =Saisie!#REF! -> #REF! | Q134: =Saisie!#REF! -> #REF! | R134: =Saisie!O134 -> 0 | S134: {=_xlfn.IFS(Saisie!#REF!="OUI",1,Saisie!#REF!="NON",0)} -> #REF! | T134: =Saisie!#REF! -> #REF! | U134: =Saisie!#REF! -> #REF! | V134: =Saisie!#REF! -> #REF! | W134: =Saisie!#REF! -> #REF! | X134: {=_xlfn.IFS(Saisie!#REF!="OUI",1,Saisie!#REF!="NON",0)} -> #REF! | Y134: {=_xlfn.IFS(Saisie!P134="OUI",1,Saisie!P134="NON",0)} -> #N/A | Z134: =Saisie!Q134 -> 0 | AA134: =Saisie!R134 -> 0 | AB134: {=_xlfn.IFS(Saisie!S134="OUI",1,Saisie!S134="NON",0)} -> #N/A | AC134: =Saisie!T134 -> 0 | AD134: =Saisie!U134 -> 0 | AE134: =Saisie!V134 -> 0 | AF134: =Saisie!W134 -> 0 | AG134: =Saisie!X134 -> 0 | AH134: =Saisie!Y134 -> 0 | AI134: =Saisie!Z134 -> 0 | AJ134: =Saisie!AA134 -> #REF! | AK134: =Saisie!AB134 -> 0 | AL134: {=_xlfn.IFS(Saisie!AC134="OUI",1,Saisie!AC134="NON",0)} -> #N/A | AM134: {=_xlfn.IFS(Saisie!AD134="Complet",1,Saisie!AD134="Incomplet",0)} -> #N/A | AN134: =Saisie!AE134 -> 0 | AO134: =Saisie!AF134 -> 0
A135: 129 | B135: =Saisie!B135 -> 0 | C135: =Saisie!C135 -> 0 | D135: =Saisie!D135 -> 0 | E135: =Saisie!E135 -> 0 | F135: =Saisie!F135 -> 0 | G135: =Saisie!G135 -> 0 | H135: =Saisie!I135 -> 0 | I135: =Saisie!J135 -> 0 | J135: =Saisie!K135 -> 0 | K135: =Saisie!L135 -> 0 | L135: =Saisie!L135 -> 0 | M135: =Saisie!#REF! -> #REF! | N135: =Saisie!#REF! -> #REF! | O135: {=_xlfn.IFS(Saisie!N135="OUI",1,Saisie!N135="NON",0)} -> #N/A | P135: =Saisie!#REF! -> #REF! | Q135: =Saisie!#REF! -> #REF! | R135: =Saisie!O135 -> 0 | S135: {=_xlfn.IFS(Saisie!#REF!="OUI",1,Saisie!#REF!="NON",0)} -> #REF! | T135: =Saisie!#REF! -> #REF! | U135: =Saisie!#REF! -> #REF! | V135: =Saisie!#REF! -> #REF! | W135: =Saisie!#REF! -> #REF! | X135: {=_xlfn.IFS(Saisie!#REF!="OUI",1,Saisie!#REF!="NON",0)} -> #REF! | Y135: {=_xlfn.IFS(Saisie!P135="OUI",1,Saisie!P135="NON",0)} -> #N/A | Z135: =Saisie!Q135 -> 0 | AA135: =Saisie!R135 -> 0 | AB135: {=_xlfn.IFS(Saisie!S135="OUI",1,Saisie!S135="NON",0)} -> #N/A | AC135: =Saisie!T135 -> 0 | AD135: =Saisie!U135 -> 0 | AE135: =Saisie!V135 -> 0 | AF135: =Saisie!W135 -> 0 | AG135: =Saisie!X135 -> 0 | AH135: =Saisie!Y135 -> 0 | AI135: =Saisie!Z135 -> 0 | AJ135: =Saisie!AA135 -> #REF! | AK135: =Saisie!AB135 -> 0 | AL135: {=_xlfn.IFS(Saisie!AC135="OUI",1,Saisie!AC135="NON",0)} -> #N/A | AM135: {=_xlfn.IFS(Saisie!AD135="Complet",1,Saisie!AD135="Incomplet",0)} -> #N/A | AN135: =Saisie!AE135 -> 0 | AO135: =Saisie!AF135 -> 0
A136: 130 | B136: =Saisie!B136 -> 0 | C136: =Saisie!C136 -> 0 | D136: =Saisie!D136 -> 0 | E136: =Saisie!E136 -> 0 | F136: =Saisie!F136 -> 0 | G136: =Saisie!G136 -> 0 | H136: =Saisie!I136 -> 0 | I136: =Saisie!J136 -> 0 | J136: =Saisie!K136 -> 0 | K136: =Saisie!L136 -> 0 | L136: =Saisie!L136 -> 0 | M136: =Saisie!#REF! -> #REF! | N136: =Saisie!#REF! -> #REF! | O136: {=_xlfn.IFS(Saisie!N136="OUI",1,Saisie!N136="NON",0)} -> #N/A | P136: =Saisie!#REF! -> #REF! | Q136: =Saisie!#REF! -> #REF! | R136: =Saisie!O136 -> 0 | S136: {=_xlfn.IFS(Saisie!#REF!="OUI",1,Saisie!#REF!="NON",0)} -> #REF! | T136: =Saisie!#REF! -> #REF! | U136: =Saisie!#REF! -> #REF! | V136: =Saisie!#REF! -> #REF! | W136: =Saisie!#REF! -> #REF! | X136: {=_xlfn.IFS(Saisie!#REF!="OUI",1,Saisie!#REF!="NON",0)} -> #REF! | Y136: {=_xlfn.IFS(Saisie!P136="OUI",1,Saisie!P136="NON",0)} -> #N/A | Z136: =Saisie!Q136 -> 0 | AA136: =Saisie!R136 -> 0 | AB136: {=_xlfn.IFS(Saisie!S136="OUI",1,Saisie!S136="NON",0)} -> #N/A | AC136: =Saisie!T136 -> 0 | AD136: =Saisie!U136 -> 0 | AE136: =Saisie!V136 -> 0 | AF136: =Saisie!W136 -> 0 | AG136: =Saisie!X136 -> 0 | AH136: =Saisie!Y136 -> 0 | AI136: =Saisie!Z136 -> 0 | AJ136: =Saisie!AA136 -> #REF! | AK136: =Saisie!AB136 -> 0 | AL136: {=_xlfn.IFS(Saisie!AC136="OUI",1,Saisie!AC136="NON",0)} -> #N/A | AM136: {=_xlfn.IFS(Saisie!AD136="Complet",1,Saisie!AD136="Incomplet",0)} -> #N/A | AN136: =Saisie!AE136 -> 0 | AO136: =Saisie!AF136 -> 0
A137: 131 | B137: =Saisie!B137 -> 0 | C137: =Saisie!C137 -> 0 | D137: =Saisie!D137 -> 0 | E137: =Saisie!E137 -> 0 | F137: =Saisie!F137 -> 0 | G137: =Saisie!G137 -> 0 | H137: =Saisie!I137 -> 0 | I137: =Saisie!J137 -> 0 | J137: =Saisie!K137 -> 0 | K137: =Saisie!L137 -> 0 | L137: =Saisie!L137 -> 0 | M137: =Saisie!#REF! -> #REF! | N137: =Saisie!#REF! -> #REF! | O137: {=_xlfn.IFS(Saisie!N137="OUI",1,Saisie!N137="NON",0)} -> #N/A | P137: =Saisie!#REF! -> #REF! | Q137: =Saisie!#REF! -> #REF! | R137: =Saisie!O137 -> 0 | S137: {=_xlfn.IFS(Saisie!#REF!="OUI",1,Saisie!#REF!="NON",0)} -> #REF! | T137: =Saisie!#REF! -> #REF! | U137: =Saisie!#REF! -> #REF! | V137: =Saisie!#REF! -> #REF! | W137: =Saisie!#REF! -> #REF! | X137: {=_xlfn.IFS(Saisie!#REF!="OUI",1,Saisie!#REF!="NON",0)} -> #REF! | Y137: {=_xlfn.IFS(Saisie!P137="OUI",1,Saisie!P137="NON",0)} -> #N/A | Z137: =Saisie!Q137 -> 0 | AA137: =Saisie!R137 -> 0 | AB137: {=_xlfn.IFS(Saisie!S137="OUI",1,Saisie!S137="NON",0)} -> #N/A | AC137: =Saisie!T137 -> 0 | AD137: =Saisie!U137 -> 0 | AE137: =Saisie!V137 -> 0 | AF137: =Saisie!W137 -> 0 | AG137: =Saisie!X137 -> 0 | AH137: =Saisie!Y137 -> 0 | AI137: =Saisie!Z137 -> 0 | AJ137: =Saisie!AA137 -> #REF! | AK137: =Saisie!AB137 -> 0 | AL137: {=_xlfn.IFS(Saisie!AC137="OUI",1,Saisie!AC137="NON",0)} -> #N/A | AM137: {=_xlfn.IFS(Saisie!AD137="Complet",1,Saisie!AD137="Incomplet",0)} -> #N/A | AN137: =Saisie!AE137 -> 0 | AO137: =Saisie!AF137 -> #REF!
A138: 132 | B138: =Saisie!B138 -> 0 | C138: =Saisie!C138 -> 0 | D138: =Saisie!D138 -> 0 | E138: =Saisie!E138 -> 0 | F138: =Saisie!F138 -> 0 | G138: =Saisie!G138 -> 0 | H138: =Saisie!I138 -> 0 | I138: =Saisie!J138 -> 0 | J138: =Saisie!K138 -> 0 | K138: =Saisie!L138 -> 0 | L138: =Saisie!L138 -> 0 | M138: =Saisie!#REF! -> #REF! | N138: =Saisie!#REF! -> #REF! | O138: {=_xlfn.IFS(Saisie!N138="OUI",1,Saisie!N138="NON",0)} -> #N/A | P138: =Saisie!#REF! -> #REF! | Q138: =Saisie!#REF! -> #REF! | R138: =Saisie!O138 -> 0 | S138: {=_xlfn.IFS(Saisie!#REF!="OUI",1,Saisie!#REF!="NON",0)} -> #REF! | T138: =Saisie!#REF! -> #REF! | U138: =Saisie!#REF! -> #REF! | V138: =Saisie!#REF! -> #REF! | W138: =Saisie!#REF! -> #REF! | X138: {=_xlfn.IFS(Saisie!#REF!="OUI",1,Saisie!#REF!="NON",0)} -> #REF! | Y138: {=_xlfn.IFS(Saisie!P138="OUI",1,Saisie!P138="NON",0)} -> #N/A | Z138: =Saisie!Q138 -> 0 | AA138: =Saisie!R138 -> 0 | AB138: {=_xlfn.IFS(Saisie!S138="OUI",1,Saisie!S138="NON",0)} -> #N/A | AC138: =Saisie!T138 -> 0 | AD138: =Saisie!U138 -> 0 | AE138: =Saisie!V138 -> 0 | AF138: =Saisie!W138 -> 0 | AG138: =Saisie!X138 -> 0 | AH138: =Saisie!Y138 -> 0 | AI138: =Saisie!Z138 -> 0 | AJ138: =Saisie!AA138 -> #REF! | AK138: =Saisie!AB138 -> 0 | AL138: {=_xlfn.IFS(Saisie!AC138="OUI",1,Saisie!AC138="NON",0)} -> #N/A | AM138: {=_xlfn.IFS(Saisie!AD138="Complet",1,Saisie!AD138="Incomplet",0)} -> #N/A | AN138: =Saisie!AE138 -> 0 | AO138: =Saisie!AF138 -> #REF!
... A1386: 1380 | B1386: =Saisie!B1386 -> 0 | C1386: =Saisie!C1386 -> 0 | D1386: =Saisie!D1386 -> 0 | E1386: =Saisie!E1386 -> 0 | F1386: =Saisie!F1386 -> 0 | G1386: =Saisie!G1386 -> 0 | H1386: =Saisie!I1386 -> 0 | I1386: =Saisie!J1386 -> 0 | J1386: =Saisie!K1386 -> 0 | K1386: =Saisie!L1386 -> 0 | L1386: =Saisie!L1386 -> 0 | M1386: =Saisie!#REF! -> #REF! | N1386: =Saisie!#REF! -> #REF! | O1386: {=_xlfn.IFS(Saisie!N1386="OUI",1,Saisie!N1386="NON",0)} -> #N/A | P1386: =Saisie!#REF! -> #REF! | Q1386: =Saisie!#REF! -> #REF! | R1386: =Saisie!O1386 -> 0 | S1386: {=_xlfn.IFS(Saisie!#REF!="OUI",1,Saisie!#REF!="NON",0)} -> #REF! | T1386: =Saisie!#REF! -> #REF! | U1386: =Saisie!#REF! -> #REF! | V1386: =Saisie!#REF! -> #REF! | W1386: =Saisie!#REF! -> #REF! | X1386: {=_xlfn.IFS(Saisie!#REF!="OUI",1,Saisie!#REF!="NON",0)} -> #REF! | Y1386: {=_xlfn.IFS(Saisie!P1386="OUI",1,Saisie!P1386="NON",0)} -> #N/A | Z1386: =Saisie!Q1386 -> 0 | AA1386: =Saisie!R1386 -> 0 | AB1386: {=_xlfn.IFS(Saisie!S1386="OUI",1,Saisie!S1386="NON",0)} -> #N/A | AC1386: =Saisie!T1386 -> 0 | AD1386: =Saisie!U1386 -> 0 | AE1386: =Saisie!V1386 -> 0 | AF1386: =Saisie!W1386 -> 0 | AG1386: =Saisie!X1386 -> 0 | AH1386: =Saisie!Y1386 -> 0 | AI1386: =Saisie!Z1386 -> 0 | AJ1386: =Saisie!AA1386 -> 0 | AK1386: =Saisie!AB1386 -> 0 | AL1386: {=_xlfn.IFS(Saisie!AC1386="OUI",1,Saisie!AC1386="NON",0)} -> #N/A | AM1386: {=_xlfn.IFS(Saisie!AD1386="Complet",1,Saisie!AD1386="Incomplet",0)} -> #N/A | AN1386: =Saisie!AE1386 -> 0 | AO1386: =Saisie!AF1386 -> #REF!
B1387: Total | K1387: =SUM(K7:K1386) -> 0 | O1387: =SUMIF(O7:O1386,1,O7:O1386) -> 0 | S1387: =SUMIF(S7:S1386,1,S7:S1386) -> 0 | X1387: =SUMIF(X7:X1386,1,X7:X1386) -> 0 | Y1387: =SUMIF(Y7:Y1386,1,Y7:Y1386) -> 0 | AB1387: =SUMIF(AB7:AB1386,1,AB7:AB1386) -> 0 | AH1387: =SUM(AH7:AH1386) -> 0 | AL1387: =SUMIF(AL7:AL1386,1,AL7:AL1386) -> 0 | AM1387: =SUMIF(AM7:AM1386,1,AM7:AM1386) -> 0

Sheet Tableau
A2: Tableau: Préparation de la Commande des opérations et date d’engagement de la dépense en PSD
A4: Opération contrôlées | B4: Planification des Opérations | D4: Respect du PSPM | F4: Date de l’engagement de la dépense
A5: Total PSC | B5: Nb | C5: %Nb | D5: Nb | E5: %Nb | F5: Nb | G5: %Nb
A6: 1483 | B6: 339 | C6: 22.9 | D6: 275 | E6: 18.5 | F6: 192 | G6: 12.9
A7: Source : DGMP
A12: Tableau 7: Repartition par type de marchés
A14: Type | B14: Nombre | C14: % du nombre | D14: Montant | E14: % du montant
A15: Fournitures | B15: =COUNTIF(Formule!J7:J1386,"FOURNITURES") -> 0 | C15: =B15/$B$18*100 -> #DIV/0! | D15: =SUMIFS(Formule!AH7:AH1386,Formule!J7:J1386,"Fournitures") -> 0 | E15: =D15/$D$18*100 -> #DIV/0!
A16: Prestations | B16: =COUNTIF(Formule!J7:J1386,"PRESTATIONS") -> 0 | C16: =B16/$B$18*100 -> #DIV/0! | D16: =SUMIFS(Formule!AH8:AH1387,Formule!J7:J1386,"Fournitures") -> 0 | E16: =D16/$D$18*100 -> #DIV/0!
A17: Travaux | B17: =COUNTIF(Formule!J7:J1386,"TRAVAUX") -> 0 | C17: =B17/$B$18*100 -> #DIV/0! | D17: =SUMIFS(Formule!AH7:AH1386,Formule!J7:J1386,"Travaux") -> 0 | E17: =D17/$D$18*100 -> #DIV/0!
A18: Total | B18: =SUM(B15:B17) -> 0 | C18: =SUM(C15:C17) -> #DIV/0! | D18: =SUM(D15:D17) -> 0 | E18: =SUM(E15:E17) -> #DIV/0!

Sheet QUESTIONNAIRE
A1: Id | B1: Directive (arrêté n°112/ MPMBPE/DGBF/ DMP du 08 mars 2016) | C1: Niveau de contrôle | D1: (A) Constats (selon le constat écrire oui ou non) | E1: (B) Commentaires (indiquez l’information relative au constat) | F1: ( C) Observations (indiquez s’il y a des observations particulières)
A2: I1 | C2: Ministère | D2: 1
A3: I2 | C3: Autorité Contractante | D3: 2
A4: I3 | C4: Contrôleur | D4: 4
A5: I4 | C5: Date Contrôle | D5: 2
A6: I5 | C6: Lieu Contrôle
A7: I6 | C7: Personne Ressource
A8: I7 | C8: Numéro Opération
A9: I8 | C9: Imputation Budgétaire
A10: I9 | C10: Objet de l'Opération
A11: Q1 | B11: Articles 7, 8 et 9 | C11: Montant de la dotation :
A12: Q2 | B12: Article 6 | C12: Estimation du projet
A13: Q3 | B13: Article 5 | C13: Inscription de l’opération au PSPM
A14: Q4 | B14: Article 7 | C14: Formulaire de demande de cotation conforme au modèle élaboré par la DMP
A15: Q5 | B15: Article 7 | C15: Conformité du contenu du formulaire de demande de cotation
A16: Q6 | B16: Articles 8.1 et 9 | C16: Délai de préparation des offres
A17: Q7 | B17: Article 7 | C17: Composition du Comité de sélection
A18: Q8 | B18: Article 7 | C18: Existence d’une liste de retrait du support de consultation
A19: Q9 | B19: Article 7 | C19: Existence d’une liste de dépôt des plis
A20: Q10 | B20: Article 7 | C20: Respect de la date limite de dépôt des plis
A21: Q11 | B21: Article 7 | C21: Nombre de soumissionnaires
A22: Q12 | B22: Article 7 | C22: Composition de la liste des candidats consultés (fréquence de consultation des candidats)
... A27: Q17 | B27: Article 7 | C27: Raison sociale et NCC du ou des attributaires par lot
A28: Q18 | C28: Montant de l’attribution par lot
A29: Q19 | B29: Article 17 | C29: Respect du délai de recours éventuels
A30: Q20 | B30: Article 7 | C30: Existence d’un formulaire de sélection conforme au modèle DMP
A31: Q21 | B31: Article 7 | C31: Date de signature du contrat par l’autorité contractante
A32: Q22 | B32: Article 7 | C32: Qualité du signataire au niveau de l’autorité contractante
A33: Q23 | C33: Existence de l’archivage des documents
A34: Q24 | C34: Temps total pour la conduite de l’opération
